Workbook

Sheet All keywords
A1: Keyword | B1: Avg. monthly searches | C1: Relevant | D1: Broader/Campaign | E1: Sub Theme/Adgroup | F1: Reason | G1: Category | H1: Intent
A2: curry paste thai | B2: 3600 | C2: No | F2: Thai / foreign cuisine – wrong flavour for a Chettinad paste | G2: Generic | H2: High / Commercial
A3: thai curry paste | B3: 3600 | C3: No | F3: Thai / foreign cuisine – wrong flavour for a Chettinad paste | G3: Generic | H3: High / Commercial
A4: thai green curry paste | B4: 2900 | C4: No | F4: Thai / foreign cuisine – wrong flavour for a Chettinad paste | G4: Generic | H4: High / Commercial
A5: thai red curry paste | B5: 2400 | C5: No | F5: Thai / foreign cuisine – wrong flavour for a Chettinad paste | G5: Generic | H5: High / Commercial
A6: chicken curry masala | B6: 1300 | C6: Yes | D6: Generic | E6: Chicken Curry Masala | F6: Same cooking need (chicken curry) | G6: Generic | H6: High / Commercial
A7: chettinad masala | B7: 1000 | C7: Yes | D7: Generic | E7: Chettinad | F7: Exact cuisine match | G7: Generic | H7: High / Commercial
A8: chicken chettinad masala | B8: 720 | C8: Yes | D8: Generic | E8: Chettinad | F8: Exact cuisine match | G8: Generic | H8: High / Commercial
A9: red curry paste | B9: 720 | C9: No | F9: Thai / foreign cuisine – wrong flavour for a Chettinad paste | G9: Generic | H9: High / Commercial
A10: green curry paste | B10: 590 | C10: No | F10: Thai / foreign cuisine – wrong flavour for a Chettinad paste | G10: Generic | H10: High / Commercial
A11: real thai red curry paste | B11: 590 | C11: No | F11: Thai / foreign cuisine – wrong flavour for a Chettinad paste | G11: Generic | H11: High / Commercial
A12: mae ploy thai curry paste | B12: 480 | C12: No | F12: Thai / foreign cuisine – wrong flavour for a Chettinad paste | G12: Competitor | H12: High / Commercial
A13: massaman curry paste | B13: 480 | C13: No | F13: Thai / foreign cuisine – wrong flavour for a Chettinad paste | G13: Generic | H13: High / Commercial
A14: curry paste | B14: 390 | C14: Yes | D14: Generic | E14: Curry Paste / Ready to Cook | F14: Format match (paste / ready-to-cook) | G14: Generic | H14: High / Commercial
A15: real thai green curry paste | B15: 390 | C15: No | F15: Thai / foreign cuisine – wrong flavour for a Chettinad paste | G15: Generic | H15: High / Commercial
A16: thai yellow curry paste | B16: 320 | C16: No | F16: Thai / foreign cuisine – wrong flavour for a Chettinad paste | G16: Generic | H16: High / Commercial
A17: yellow curry paste | B17: 260 | C17: No | F17: Thai / foreign cuisine – wrong flavour for a Chettinad paste | G17: Generic | H17: High / Commercial
A18: chicken curry masala powder | B18: 170 | C18: Yes | D18: Generic | E18: Chicken Curry Masala | F18: Same cooking need (chicken curry) | G18: Generic | H18: High / Commercial
A19: maesri thai curry paste | B19: 170 | C19: No | F19: Thai / foreign cuisine – wrong flavour for a Chettinad paste | G19: Generic | H19: High / Commercial
A20: namjai green curry paste | B20: 170 | C20: No | F20: Thai / foreign cuisine – wrong flavour for a Chettinad paste | G20: Generic | H20: High / Commercial
A21: real thai curry paste | B21: 170 | C21: No | F21: Thai / foreign cuisine – wrong flavour for a Chettinad paste | G21: Generic | H21: High / Commercial
A22: thai kitchen red curry paste | B22: 170 | C22: No | F22: Thai / foreign cuisine – wrong flavour for a Chettinad paste | G22: Competitor | H22: High / Commercial
A23: chettinad masala powder | B23: 140 | C23: Yes | D23: Generic | E23: Chettinad | F23: Exact cuisine match | G23: Generic | H23: High / Commercial
A24: mdh chicken curry masala | B24: 140 | C24: Yes | D24: Competitor | E24: Chicken Curry Masala Brands | F24: Competitor brand, chicken curry masala | G24: Competitor | H24: High / Commercial
A25: sunrise chicken curry masala | B25: 140 | C25: Yes | D25: Competitor | E25: Chicken Curry Masala Brands | F25: Competitor brand, chicken curry masala | G25: Generic | H25: High / Commercial
A26: chettinad chicken masala powder | B26: 110 | C26: Yes | D26: Generic | E26: Chettinad | F26: Exact cuisine match | G26: Generic | H26: High / Commercial
A27: cookd chettinad masala | B27: 110 | C27: Yes | D27: Competitor | E27: Chettinad Competitors | F27: Competitor brand + Chettinad | G27: Generic | H27: High / Commercial
A28: curry leaves paste | B28: 110 | C28: No | F28: Single-ingredient paste, not a curry | G28: Generic | H28: High / Commercial
A29: blue elephant curry paste | B29: 90 | C29: No | F29: Thai / foreign cuisine – wrong flavour for a Chettinad paste | G29: Competitor | H29: High / Commercial
A30: blue elephant thai curry paste | B30: 90 | C30: No | F30: Thai / foreign cuisine – wrong flavour for a Chettinad paste | G30: Competitor | H30: High / Commercial
A31: chettinad biryani masala | B31: 90 | C31: No | F31: Biryani – different dish | G31: Generic | H31: High / Commercial
A32: curry it ginger garlic paste | B32: 90 | C32: No | F32: Own brand, other product – route to that product's campaign | G32: Brand | H32: High / Commercial
A33: curry paste indian | B33: 90 | C33: Yes | D33: Generic | E33: Curry Paste / Ready to Cook | F33: Format match (paste / ready-to-cook) | G33: Generic | H33: High / Commercial
A34: namjai red curry paste | B34: 90 | C34: No | F34: Thai / foreign cuisine – wrong flavour for a Chettinad paste | G34: Generic | H34: High / Commercial
A35: real thai yellow curry paste | B35: 90 | C35: No | F35: Thai / foreign cuisine – wrong flavour for a Chettinad paste | G35: Generic | H35: High / Commercial
A36: suhana chicken curry masala | B36: 90 | C36: Yes | D36: Competitor | E36: Chicken Curry Masala Brands | F36: Competitor brand, chicken curry masala | G36: Competitor | H36: High / Commercial
A37: jain thai curry paste | B37: 70 | C37: No | F37: Jain / no onion-garlic; CURRYiT contains onion & garlic | G37: Generic | H37: High / Commercial
A38: katsu curry paste | B38: 70 | C38: No | F38: Thai / foreign cuisine – wrong flavour for a Chettinad paste | G38: Generic | H38: High / Commercial
A39: knorr thai curry paste | B39: 70 | C39: No | F39: Thai / foreign cuisine – wrong flavour for a Chettinad paste | G39: Competitor | H39: High / Commercial
A40: namjai curry paste | B40: 70 | C40: No | F40: Thai / foreign cuisine – wrong flavour for a Chettinad paste | G40: Generic | H40: High / Commercial
...

Sheet Generic Kws
A1: Keyword | B1: Avg. monthly searches | C1: Relevant | D1: Broader/Campaign | E1: Sub Theme/Adgroup | F1: Reason | G1: Category | H1: Intent
A2: curry paste thai | B2: 3600 | C2: No | F2: Thai / foreign cuisine – wrong flavour for a Chettinad paste | G2: Generic | H2: High / Commercial
A3: thai curry paste | B3: 3600 | C3: No | F3: Thai / foreign cuisine – wrong flavour for a Chettinad paste | G3: Generic | H3: High / Commercial
A4: thai green curry paste | B4: 2900 | C4: No | F4: Thai / foreign cuisine – wrong flavour for a Chettinad paste | G4: Generic | H4: High / Commercial
A5: thai red curry paste | B5: 2400 | C5: No | F5: Thai / foreign cuisine – wrong flavour for a Chettinad paste | G5: Generic | H5: High / Commercial
A6: chicken curry masala | B6: 1300 | C6: Yes | D6: Generic | E6: Chicken Curry Masala | F6: Same cooking need (chicken curry) | G6: Generic | H6: High / Commercial
A7: chettinad masala | B7: 1000 | C7: Yes | D7: Generic | E7: Chettinad | F7: Exact cuisine match | G7: Generic | H7: High / Commercial
A8: chicken chettinad masala | B8: 720 | C8: Yes | D8: Generic | E8: Chettinad | F8: Exact cuisine match | G8: Generic | H8: High / Commercial
A9: red curry paste | B9: 720 | C9: No | F9: Thai / foreign cuisine – wrong flavour for a Chettinad paste | G9: Generic | H9: High / Commercial
A10: green curry paste | B10: 590 | C10: No | F10: Thai / foreign cuisine – wrong flavour for a Chettinad paste | G10: Generic | H10: High / Commercial
A11: real thai red curry paste | B11: 590 | C11: No | F11: Thai / foreign cuisine – wrong flavour for a Chettinad paste | G11: Generic | H11: High / Commercial
A12: massaman curry paste | B12: 480 | C12: No | F12: Thai / foreign cuisine – wrong flavour for a Chettinad paste | G12: Generic | H12: High / Commercial
A13: curry paste | B13: 390 | C13: Yes | D13: Generic | E13: Curry Paste / Ready to Cook | F13: Format match (paste / ready-to-cook) | G13: Generic | H13: High / Commercial
A14: real thai green curry paste | B14: 390 | C14: No | F14: Thai / foreign cuisine – wrong flavour for a Chettinad paste | G14: Generic | H14: High / Commercial
A15: thai yellow curry paste | B15: 320 | C15: No | F15: Thai / foreign cuisine – wrong flavour for a Chettinad paste | G15: Generic | H15: High / Commercial
A16: yellow curry paste | B16: 260 | C16: No | F16: Thai / foreign cuisine – wrong flavour for a Chettinad paste | G16: Generic | H16: High / Commercial
A17: chicken curry masala powder | B17: 170 | C17: Yes | D17: Generic | E17: Chicken Curry Masala | F17: Same cooking need (chicken curry) | G17: Generic | H17: High / Commercial
A18: maesri thai curry paste | B18: 170 | C18: No | F18: Thai / foreign cuisine – wrong flavour for a Chettinad paste | G18: Generic | H18: High / Commercial
A19: namjai green curry paste | B19: 170 | C19: No | F19: Thai / foreign cuisine – wrong flavour for a Chettinad paste | G19: Generic | H19: High / Commercial
A20: real thai curry paste | B20: 170 | C20: No | F20: Thai / foreign cuisine – wrong flavour for a Chettinad paste | G20: Generic | H20: High / Commercial
A21: chettinad masala powder | B21: 140 | C21: Yes | D21: Generic | E21: Chettinad | F21: Exact cuisine match | G21: Generic | H21: High / Commercial
A22: sunrise chicken curry masala | B22: 140 | C22: Yes | D22: Competitor | E22: Chicken Curry Masala Brands | F22: Competitor brand, chicken curry masala | G22: Generic | H22: High / Commercial
A23: chettinad chicken masala powder | B23: 110 | C23: Yes | D23: Generic | E23: Chettinad | F23: Exact cuisine match | G23: Generic | H23: High / Commercial
A24: cookd chettinad masala | B24: 110 | C24: Yes | D24: Competitor | E24: Chettinad Competitors | F24: Competitor brand + Chettinad | G24: Generic | H24: High / Commercial
A25: curry leaves paste | B25: 110 | C25: No | F25: Single-ingredient paste, not a curry | G25: Generic | H25: High / Commercial
A26: chettinad biryani masala | B26: 90 | C26: No | F26: Biryani – different dish | G26: Generic | H26: High / Commercial
A27: curry paste indian | B27: 90 | C27: Yes | D27: Generic | E27: Curry Paste / Ready to Cook | F27: Format match (paste / ready-to-cook) | G27: Generic | H27: High / Commercial
A28: namjai red curry paste | B28: 90 | C28: No | F28: Thai / foreign cuisine – wrong flavour for a Chettinad paste | G28: Generic | H28: High / Commercial
A29: real thai yellow curry paste | B29: 90 | C29: No | F29: Thai / foreign cuisine – wrong flavour for a Chettinad paste | G29: Generic | H29: High / Commercial
A30: jain thai curry paste | B30: 70 | C30: No | F30: Jain / no onion-garlic; CURRYiT contains onion & garlic | G30: Generic | H30: High / Commercial
A31: katsu curry paste | B31: 70 | C31: No | F31: Thai / foreign cuisine – wrong flavour for a Chettinad paste | G31: Generic | H31: High / Commercial
A32: namjai curry paste | B32: 70 | C32: No | F32: Thai / foreign cuisine – wrong flavour for a Chettinad paste | G32: Generic | H32: High / Commercial
A33: namjai thai curry paste | B33: 70 | C33: No | F33: Thai / foreign cuisine – wrong flavour for a Chettinad paste | G33: Generic | H33: High / Commercial
A34: non veg curry masala paste | B34: 70 | C34: Yes | D34: Generic | E34: Curry Paste / Ready to Cook | F34: Format match (paste / ready-to-cook) | G34: Generic | H34: High / Commercial
A35: sakthi chettinad chicken masala | B35: 70 | C35: Yes | D35: Competitor | E35: Chettinad Competitors | F35: Competitor brand + Chettinad | G35: Generic | H35: High / Commercial
A36: laksa curry paste | B36: 50 | C36: No | F36: Thai / foreign cuisine – wrong flavour for a Chettinad paste | G36: Generic | H36: High / Commercial
A37: rendang curry paste | B37: 50 | C37: No | F37: Thai / foreign cuisine – wrong flavour for a Chettinad paste | G37: Generic | H37: High / Commercial
A38: thai green curry paste vegetarian | B38: 50 | C38: No | F38: Thai / foreign cuisine – wrong flavour for a Chettinad paste | G38: Generic | H38: High / Commercial
A39: zoff chicken curry masala | B39: 50 | C39: Yes | D39: Competitor | E39: Chicken Curry Masala Brands | F39: Competitor brand, chicken curry masala | G39: Generic | H39: High / Commercial
A40: fish curry paste | B40: 40 | C40: No | F40: Other dish / other CURRYiT product – route elsewhere | G40: Generic | H40: High / Commercial
...

Sheet Brand Kws
A1: Keyword | B1: Avg. monthly searches | C1: Relevant | D1: Broader/Campaign | E1: Sub Theme/Adgroup | F1: Reason | G1: Category | H1: Intent
A2: curry it ginger garlic paste | B2: 90 | C2: No | F2: Own brand, other product – route to that product's campaign | G2: Brand | H2: High / Commercial
A3: curryit chettinad chicken curry masala paste | C3: Yes | D3: Brand | E3: Brand + Chettinad | F3: Own brand + exact product | G3: Brand | H3: High / Commercial
A4: curryit punjabi kadhai paneer masala premium cooking paste | C4: No | F4: Own brand, other product – route to that product's campaign | G4: Brand | H4: High / Commercial
A5: curryit | B5: 1300 | D5: Brand | E5: Brand | F5: Brand keyword – directly searches for CURRYiT | G5: Brand | H5: Generic / Mixed
A6: Curryit paste | D6: Brand | E6: Brand | F6: Brand keyword – directly searches for CURRYiT paste | G6: Brand | H6: High / Commercial
A7: curry it | B7: 2400 | D7: Brand | E7: Brand | F7: Brand keyword – alternate spelling of CURRYiT | G7: Brand | H7: Generic / Mixed

Sheet Comp Keywords
A1: Keyword | B1: Avg. monthly searches | C1: Relevant | D1: Broader/Campaign | E1: Sub Theme/Adgroup | F1: Reason | G1: Category | H1: Intent
A2: mae ploy thai curry paste | B2: 480 | C2: No | F2: Thai / foreign cuisine – wrong flavour for a Chettinad paste | G2: Competitor | H2: High / Commercial
A3: thai kitchen red curry paste | B3: 170 | C3: No | F3: Thai / foreign cuisine – wrong flavour for a Chettinad paste | G3: Competitor | H3: High / Commercial
A4: mdh chicken curry masala | B4: 140 | C4: Yes | D4: Competitor | E4: Chicken Curry Masala Brands | F4: Competitor brand, chicken curry masala | G4: Competitor | H4: High / Commercial
A5: blue elephant curry paste | B5: 90 | C5: No | F5: Thai / foreign cuisine – wrong flavour for a Chettinad paste | G5: Competitor | H5: High / Commercial
A6: blue elephant thai curry paste | B6: 90 | C6: No | F6: Thai / foreign cuisine – wrong flavour for a Chettinad paste | G6: Competitor | H6: High / Commercial
A7: suhana chicken curry masala | B7: 90 | C7: Yes | D7: Competitor | E7: Chicken Curry Masala Brands | F7: Competitor brand, chicken curry masala | G7: Competitor | H7: High / Commercial
A8: knorr thai curry paste | B8: 70 | C8: No | F8: Thai / foreign cuisine – wrong flavour for a Chettinad paste | G8: Competitor | H8: High / Commercial
A9: everest chicken curry masala | B9: 50 | C9: Yes | D9: Competitor | E9: Chicken Curry Masala Brands | F9: Competitor brand, chicken curry masala | G9: Competitor | H9: High / Commercial
A10: thai kitchen green curry paste | B10: 50 | C10: No | F10: Thai / foreign cuisine – wrong flavour for a Chettinad paste | G10: Competitor | H10: High / Commercial
A11: knorr green thai curry paste | B11: 40 | C11: No | F11: Thai / foreign cuisine – wrong flavour for a Chettinad paste | G11: Competitor | H11: High / Commercial
A12: aachi chicken curry masala | B12: 30 | C12: Yes | D12: Competitor | E12: Chicken Curry Masala Brands | F12: Competitor brand, chicken curry masala | G12: Competitor | H12: High / Commercial
A13: aachi curry leaf rice paste | B13: 30 | C13: No | F13: Pack size / diet / unrelated product | G13: Competitor | H13: High / Commercial
A14: blue elephant green curry paste | B14: 30 | C14: No | F14: Thai / foreign cuisine – wrong flavour for a Chettinad paste | G14: Competitor | H14: High / Commercial
A15: blue elephant thai green curry paste | B15: 30 | C15: No | F15: Thai / foreign cuisine – wrong flavour for a Chettinad paste | G15: Competitor | H15: High / Commercial
A16: itc master chef butter chicken cooking paste | B16: 30 | C16: No | F16: Other dish / other CURRYiT product – route elsewhere | G16: Competitor | H16: High / Commercial
A17: aachi chettinad chicken biryani masala | B17: 20 | C17: No | F17: Biryani – different dish | G17: Competitor | H17: High / Commercial
A18: itc cooking paste | B18: 20 | C18: Yes | D18: Competitor | E18: Cooking Paste Brands | F18: Competitor brand, same paste format | G18: Competitor | H18: High / Commercial
A19: itc master chef cooking paste | B19: 20 | C19: Yes | D19: Competitor | E19: Cooking Paste Brands | F19: Competitor brand, same paste format | G19: Competitor | H19: High / Commercial
A20: priya non veg curry masala paste | B20: 20 | C20: Yes | D20: Competitor | E20: Cooking Paste Brands | F20: Competitor brand, same paste format | G20: Competitor | H20: High / Commercial
A21: aachi chettinad chicken masala | B21: 10 | C21: Yes | D21: Competitor | E21: Chettinad Competitors | F21: Competitor brand + Chettinad | G21: Competitor | H21: High / Commercial
A22: blue elephant red thai curry paste | B22: 10 | C22: No | F22: Thai / foreign cuisine – wrong flavour for a Chettinad paste | G22: Competitor | H22: High / Commercial
A23: itc masterchef cooking paste | B23: 10 | C23: Yes | D23: Competitor | E23: Cooking Paste Brands | F23: Competitor brand, same paste format | G23: Competitor | H23: High / Commercial
A24: shan chicken curry masala | B24: 10 | C24: Yes | D24: Competitor | E24: Chicken Curry Masala Brands | F24: Competitor brand, chicken curry masala | G24: Competitor | H24: High / Commercial
A25: aachi chettinad masala | C25: Yes | D25: Competitor | E25: Chettinad Competitors | F25: Competitor brand + Chettinad | G25: Competitor | H25: High / Commercial
A26: chettinad masala mtr | C26: Yes | D26: Competitor | E26: Chettinad Competitors | F26: Competitor brand + Chettinad | G26: Competitor | H26: High / Commercial
A27: itc butter chicken cooking paste | C27: No | F27: Other dish / other CURRYiT product – route elsewhere | G27: Competitor | H27: High / Commercial
A28: itc curry paste | C28: Yes | D28: Competitor | E28: Cooking Paste Brands | F28: Competitor brand, same paste format | G28: Competitor | H28: High / Commercial
A29: mother's recipe chicken curry masala | C29: Yes | D29: Competitor | E29: Chicken Curry Masala Brands | F29: Competitor brand, chicken curry masala | G29: Competitor | H29: High / Commercial
A30: mothers recipe chicken chettinad masala | C30: Yes | D30: Competitor | E30: Chettinad Competitors | F30: Competitor brand + Chettinad | G30: Competitor | H30: High / Commercial
A31: saffola masala oats chicken curry flavour | C31: No | F31: Pack size / diet / unrelated product | G31: Competitor | H31: High / Commercial
A32: tata sampann chicken curry masala | C32: Yes | D32: Competitor | E32: Chicken Curry Masala Brands | F32: Competitor brand, chicken curry masala | G32: Competitor | H32: High / Commercial

Sheet SP Campaign
B1: SPONSERED Product – Chettinad Chicken Curry Paste
A2: ASIN- B0G1YXWM2P
A4: Campaign Objective | B4: Campaign Name | C4: Ad grp Name | D4: Bidding Strategy | E4: Advertised Product | F4: Targetting | G4: Negative Targetting
B5: Auto
A7: Conversion | B7: SP/ChettinadChicken /Auto | C7: ChettinadChicken-Auto | D7: Down only | E7: B0G1YXWM2P | F7: - Close - Loose - Substitute - Complements | G7: Negate in Exact: curry it curryit chicken curry masala chettinad masala chicken chettinad masala curry paste chicken curry masala powder chettinad masala powder chicken curry masala chettinad chicken masala powder cookd chettinad masala curry paste indian non veg curry masala paste sakthi chettinad chicken masala zoff chicken curry masala ready to cook curry mutton curry paste ready to cook chicken curry cooking pastes india gate chettinad chicken masala india gate classic chettinad chicken masala ready to cook curry paste mdh chicken curry masala suhana chicken curry masala everest chicken curry masala aachi chicken curry masala itc cooking paste itc master chef cooking paste priya non veg curry masala paste aachi chettinad chicken masala itc masterchef cooking paste shan chicken curry masala Negate Product: B079H3DFP7 B0FLP9NYR1 B07BH4B384 B08MFLHMJC B0CY8KKGGP B09BD5VW64 B09BD5BNJ7 B0917NY7X6 B09BD583S6 B08H284SNC B0777JV82Z B0BV76DCY6 B0DPJ3P467 B0C53VBXVM B0BV7783X7 B0C58S9P1K B0G1YZ3K4T B0G1Z87RV9 B0CL9D1PHY B0G1YZ5K91
B9: Brand KW
A10: Conversion | B10: SP/ChettinadChicken/Brand KWs/Exact | C10: ChettinadChicken-Brand Kws- Exact | D10: Up and Down | E10: B0G1YXWM2P | F10: curry it curryit | G10: NA
A12: Conversion | B12: SP/ChettinadChicken/Brand KWs/Phrase | C12: ChettinadChicken-Brand Kws- Phrase | D12: Up and Down | E12: B0G1YXWM2P | F12: curry it curryit | G12: Negate In EXACT curry it curryit
A14: Conversion | B14: SP/ChettinadChicken/Brand KWs/Broad | C14: ChettinadChicken-Brand Kws- Broad | D14: Down Only | E14: B0G1YXWM2P | F14: curry it curryit | G14: Negate In Phrase curry it curryit
B16: Generic KWS
A17: Conversion | B17: SP/ChettinadChicken/Generic KWs/Exact | C17: ChettinadChicken-Geneirc Kws- Exact | D17: Up and Down | E17: B0G1YXWM2P | F17: chicken curry masala chettinad masala chicken chettinad masala curry paste chicken curry masala powder chettinad masala powder chicken curry masala chettinad chicken masala powder cookd chettinad masala curry paste indian non veg curry masala paste ready to cook curry mutton curry paste ready to cook chicken curry cooking pastes ready to cook curry paste | G17: NA
A19: Conversion | B19: SP/ChettinadChicken/Generic KWs/Phrase | C19: ChettinadChicken-Geneirc Kws- Phrase | D19: Up and Down | E19: B0G1YXWM2P | F19: chicken curry masala chettinad masala chicken chettinad masala curry paste chicken curry masala powder chettinad masala powder chicken curry masala chettinad chicken masala powder cookd chettinad masala curry paste indian non veg curry masala paste ready to cook curry mutton curry paste ready to cook chicken curry cooking pastes ready to cook curry paste | G19: Negate in exact- chicken curry masala chettinad masala chicken chettinad masala curry paste chicken curry masala powder chettinad masala powder chicken curry masala chettinad chicken masala powder cookd chettinad masala curry paste indian non veg curry masala paste ready to cook curry mutton curry paste ready to cook chicken curry cooking pastes ready to cook curry paste
A21: Conversion | B21: SP/ChettinadChicken/Generic KWs/Broad | C21: ChettinadChicken-Geneirc Kws- Broad | D21: Down Only | E21: B0G1YXWM2P | F21: chicken curry masala chettinad masala chicken chettinad masala curry paste chicken curry masala powder chettinad masala powder chicken curry masala chettinad chicken masala powder cookd chettinad masala curry paste indian non veg curry masala paste ready to cook curry mutton curry paste ready to cook chicken curry cooking pastes ready to cook curry paste | G21: Negate in Phrase- chicken curry masala chettinad masala chicken chettinad masala curry paste chicken curry masala powder chettinad masala powder chicken curry masala chettinad chicken masala powder cookd chettinad masala curry paste indian non veg curry masala paste ready to cook curry mutton curry paste ready to cook chicken curry cooking pastes ready to cook curry paste
B23: Competitiors Kws
A25: Consideration/ Awarness | B25: SP/ChettinadChicken/Comp KWs/Exact | C25: ChettinadChicken-Comp Kws- Exact | D25: Down Only | E25: B0G1YXWM2P | F25: mdh chicken curry masala suhana chicken curry masala everest chicken curry masala aachi chicken curry masala itc cooking paste itc master chef cooking paste priya non veg curry masala paste aachi chettinad chicken masala itc masterchef cooking paste shan chicken curry masala | G25: NA
A27: Consideration/ Awarness | B27: SP/ChettinadChicken/Comp KWs/Phrase | C27: ChettinadChicken-Comp Kws- Phrase | D27: Down Only | E27: B0G1YXWM2P | F27: mdh chicken curry masala suhana chicken curry masala everest chicken curry masala aachi chicken curry masala itc cooking paste itc master chef cooking paste priya non veg curry masala paste aachi chettinad chicken masala itc masterchef cooking paste shan chicken curry masala | G27: Negate in exact- mdh chicken curry masala suhana chicken curry masala everest chicken curry masala aachi chicken curry masala itc cooking paste itc master chef cooking paste priya non veg curry masala paste aachi chettinad chicken masala itc masterchef cooking paste shan chicken curry masala
A29: Consideration/ Awarness | B29: SP/ChettinadChicken/Comp KWs/Broad | C29: ChettinadChicken-Comp Kws- Broad | D29: Down Only | E29: B0G1YXWM2P | F29: mdh chicken curry masala suhana chicken curry masala everest chicken curry masala aachi chicken curry masala itc cooking paste itc master chef cooking paste priya non veg curry masala paste aachi chettinad chicken masala itc masterchef cooking paste shan chicken curry masala | G29: Negate in Phrase- mdh chicken curry masala suhana chicken curry masala everest chicken curry masala aachi chicken curry masala itc cooking paste itc master chef cooking paste priya non veg curry masala paste aachi chettinad chicken masala itc masterchef cooking paste shan chicken curry masala
B31: Category
A33: Awareness | B33: SP/Whey Protein/CT | C33: ChettinadChicken- CT | D33: Down Only | E33: B0G1YXWM2P | F33: Cooking & Baking Supplies›Spices & Masalas›Powdered Spices, Seasonings & Masalas›Mixed Spices & Seasonings›Ready Masalas & Curry Powder | G33: Negate in exact- B079H3DFP7 B0FLP9NYR1 B07BH4B384 B08MFLHMJC B0CY8KKGGP B09BD5VW64 B09BD5BNJ7 B0917NY7X6 B09BD583S6 B08H284SNC B0777JV82Z B0BV76DCY6 B0DPJ3P467 B0C53VBXVM B0BV7783X7 B0C58S9P1K
B35: Individual
A37: Consideration | B37: SP/Whey Protein/IP/CompTar | C37: ChettinadChicken- IP | D37: Down Only | E37: B0G1YXWM2P | F37: B079H3DFP7 B0FLP9NYR1 B07BH4B384 B08MFLHMJC B0CY8KKGGP B09BD5VW64 B09BD5BNJ7 B0917NY7X6 B09BD583S6 B08H284SNC B0777JV82Z B0BV76DCY6 B0DPJ3P467 B0C53VBXVM B0BV7783X7 B0C58S9P1K | G37: NA
A39: Conversion | B39: SP/Whey Protein/IP/BrandTar | C39: ChettinadChicken- IP | D39: Down Only | E39: B0G1YXWM2P | F39: B0G1YZ3K4T B0G1Z87RV9 B0CL9D1PHY B0G1YZ5K91 | G39: NA

Sheet SB Campaign
B1: SPONSERED BRAND (SB) – ChettinadChicken Chettinad Chicken Curry Paste
A2: Campaign Objective | B2: Campaign Name | C2: Ad grp Name | D2: Advertised Product | E2: Ad Format | F2: Targeting | G2: Negative Targeting
A3: Conversion | B3: SB/ChettinadChicken/Video/Brand kws-Exact | C3: Video - Brand Exact | D3: B0G1YXWM2P | E3: Video | F3: curry it curryit | G3: N/A
A7: Conversion | B7: SB/ChettinadChicken/Video/Brand kws-Pharse | C7: Video - Brand Pharse | D7: B0G1YXWM2P | E7: Video | F7: curry it curryit | G7: Negate in Exact curry it curryit
A12: Conversion | B12: SB/ChettinadChicken/Video/Generic Chettinad kws-Exact | C12: Video - Chettinad Exact | D12: B0G1YXWM2P | E12: Video | F12: chicken curry masala chettinad masala chicken chettinad masala curry paste chicken curry masala powder chettinad masala powder chicken curry masala chettinad chicken masala powder cookd chettinad masala curry paste indian non veg curry masala paste ready to cook curry mutton curry paste ready to cook chicken curry cooking pastes ready to cook curry paste | G12: N/A
A19: Conversion/ Awarenss | B19: SB/ChettinadChicken/Video/Generic Chettinad kws-Pharse | C19: Video - Chettinad Pharse | D19: B0G1YXWM2P | E19: Video | F19: chicken curry masala chettinad masala chicken chettinad masala curry paste chicken curry masala powder chettinad masala powder chicken curry masala chettinad chicken masala powder cookd chettinad masala curry paste indian non veg curry masala paste ready to cook curry mutton curry paste ready to cook chicken curry cooking pastes ready to cook curry paste | G19: Negate in Exact chicken curry masala chettinad masala chicken chettinad masala curry paste chicken curry masala powder chettinad masala powder chicken curry masala chettinad chicken masala powder cookd chettinad masala curry paste indian non veg curry masala paste ready to cook curry mutton curry paste ready to cook chicken curry cooking pastes ready to cook curry paste
A27: Consideration/ Awareness | B27: SB/ChettinadChicken/Video/Comp Chettinad kws-Exact | C27: Video - Comp Chettinad Exact | D27: B0G1YXWM2P | E27: Video | F27: mdh chicken curry masala suhana chicken curry masala everest chicken curry masala aachi chicken curry masala itc cooking paste itc master chef cooking paste priya non veg curry masala paste aachi chettinad chicken masala itc masterchef cooking paste shan chicken curry masala | G27: N/A
A38: Consideration/ Awareness | B38: SB/ChettinadChicken/Video/Comp Chettinad kws-Pharse | C38: Video - Comp Chettinad Pharse | D38: B0G1YXWM2P | E38: Video | F38: mdh chicken curry masala suhana chicken curry masala everest chicken curry masala aachi chicken curry masala itc cooking paste itc master chef cooking paste priya non veg curry masala paste aachi chettinad chicken masala itc masterchef cooking paste shan chicken curry masala | G38: Negate in Exact mdh chicken curry masala suhana chicken curry masala everest chicken curry masala aachi chicken curry masala itc cooking paste itc master chef cooking paste priya non veg curry masala paste aachi chettinad chicken masala itc masterchef cooking paste shan chicken curry masala

Sheet SD Campaign
B1: SPONSORED DISPLAY (SD) – Contextual Chettinad Chicken Curry Paste
A2: Campaign Objective | B2: Campaign Name | C2: Ad grp Name | D2: Ad Format | E2: Advertised Product | F2: Targeting
A3: Consideration | B3: SD/Chettinad Chicken/Contextual/IP | C3: Chettinad Paste/Contextual/IP-Comp Curry Paste | D3: Video | E3: B0G1YXWM2P | F3: B079H3DFP7 B0FLP9NYR1 B07BH4B384 B08MFLHMJC B0CY8KKGGP B09BD5VW64 B09BD5BNJ7 B0917NY7X6 B09BD583S6 B08H284SNC B0777JV82Z B0BV76DCY6 B0DPJ3P467 B0C53VBXVM B0BV7783X7 B0C58S9P1K
A5: Consideration | B5: SD/Contextual/Contextual/CT | C5: Chettinad Paste/Contextual/CT-Pastes | D5: Video | E5: B0G1YXWM2P | F5: Cooking & Baking Supplies›Spices & Masalas›Powdered Spices, Seasonings & Masalas›Mixed Spices & Seasonings›Ready Masalas & Curry Powder
A7: Conversion | B7: SD/Contextual/Remarketing/Views | C7: Chettinad Paste/Remarketing/Views | D7: Video | E7: B0G1YXWM2P | F7: Viewed>Advertised>Product, Viewed>Similar Product, Viewed>Category Lookback Period>7Days
A9: Conversion | B9: SD/Contextual/Remarketing/Purchases | C9: Chettinad Paste/Remarketing/Purchase | D9: Video | E9: B0G1YXWM2P | F9: Purchased>Advertised>Product, Purchased>Similar Product, Purchased>Category Lookback Period>30Days
A11: Conversion | B11: SD/Contextual/Inmarketing | C11: Chettinad Paste/Inmarketing | D11: Video | E11: B0G1YXWM2P | F11: In-market: Spices & Masalas In-market: Cooking Pastes & Sauces In-market: Ready to Cook Foods
A13: Conversion | B13: SD/Chettinad Chicken/Contextual/IP | C13: Chettinad Paste/Contextual/IP-Brand Curry Paste | D13: Video | E13: B0G1YXWM2P | F13: B0G1YZ3K4T B0G1Z87RV9 B0CL9D1PHY B0G1YZ5K91

Sheet Media Planning
A3: Media Plan
A4: Duration | B4: Spend | C4: Impressions | D4: CPM | E4: CTR | F4: Clicks | G4: CPC | H4: Sales | I4: Orders | J4: CVR | K4: CPA | L4: AOV | M4: ACOS | N4: Roas
A5: Month 1 | B5: =H5/N5 | C5: =F5/E5 | D5: =B5/C5*1000 | E5: 0.004 | F5: =B5/G5 | G5: 12 | H5: 300000 | I5: =H5/L5 | J5: 0.08 | K5: =B5/I5 | L5: 450 | M5: =B5/H5 | N5: 3
A6: Month 2 | B6: =H6/N6 | C6: =F6/E6 | D6: =B6/C6*1000 | E6: 0.004 | F6: =B6/G6 | G6: 12 | H6: 300000 | I6: =H6/L6 | J6: 0.08 | K6: =B6/I6 | L6: 450 | M6: =B6/H6 | N6: 3
A7: Month 3 | B7: =H7/N7 | C7: =F7/E7 | D7: =B7/C7*1000 | E7: 0.004 | F7: =B7/G7 | G7: 12 | H7: 600000 | I7: =H7/L7 | J7: 0.08 | K7: =B7/I7 | L7: 450 | M7: =B7/H7 | N7: 3
A8: Month 4 | B8: =H8/N8 | C8: =F8/E8 | D8: =B8/C8*1000 | E8: 0.004 | F8: =B8/G8 | G8: 12 | H8: 600000 | I8: =H8/L8 | J8: 0.08 | K8: =B8/I8 | L8: 450 | M8: =B8/H8 | N8: 3
A9: Month 5 | B9: =H9/N9 | C9: =F9/E9 | D9: =B9/C9*1000 | E9: 0.004 | F9: =B9/G9 | G9: 12 | H9: 1000000 | I9: =H9/L9 | J9: 0.08 | K9: =B9/I9 | L9: 450 | M9: =B9/H9 | N9: 3
A10: Month 6 | B10: =H10/N10 | C10: =F10/E10 | D10: =B10/C10*1000 | E10: 0.004 | F10: =B10/G10 | G10: 12 | H10: 1000000 | I10: =H10/L10 | J10: 0.08 | K10: =B10/I10 | L10: 450 | M10: =B10/H10 | N10: 3
B13: Assumed | C13: Reason
B14: ACOS | C14: Assumed the ACOS as per benchmark which is highest at the awareness stage and goes down gradually down the funnel.
B15: CTR | C15: Assumed the CTR as per benchmark which is lowest at the awareness stage and goes up gradually down the funnel.
B16: CPC | C16: Assumed the CPC as per benchmark which is highest at the awareness stage and goes down gradually down the funnel.
B17: AOV | C17: Assumed the AOV as 1000 that is by taking the average of the 3 plant products pricing .

Sheet Budget Split
A1: Budget Split – CURRYiT Chettinad (Month-wise, as per CURRYiT deck phases)
A3: A. Campaign type split (%)
A4: Campaign type | B4: Month 1 | C4: Month 2 | D4: Month 3 | E4: Month 4 | F4: Month 5 | G4: Month 6 | H4: Phase logic
A5: SP Keywords (Brand / Generic / Comp) | B5: 0.45 | C5: 0.45 | D5: 0.35 | E5: 0.35 | F5: 0.32 | G5: 0.32 | H5: Biggest bucket all 6 months. Tightest targeting, best ROAS (deck).
A6: SP Auto | B6: 0.2 | C6: 0.2 | D6: 0.1 | E6: 0.1 | F6: 0.08 | G6: 0.08 | H6: High in M1–2 to find keywords; cut later as winners move to Exact.
A7: SP Product Targeting (CT + IP) | B7: 0.2 | C7: 0.2 | D7: 0.15 | E7: 0.15 | F7: 0.12 | G7: 0.12 | H7: Show ad on competitor pages from day 1 (deck).
A8: SB Video | B8: 0.15 | C8: 0.15 | D8: 0.15 | E8: 0.15 | F8: 0.15 | G8: 0.15 | H8: 15-min cooking video = best format for food (deck). Flat all months.
A9: SB Brand (combo) – new | B9: 0 | C9: 0 | D9: 0.1 | E9: 0.1 | F9: 0.15 | G9: 0.15 | H9: Deck rule: start in Month 3, sells the combo not the single pouch.
A10: SD (Retargeting + Audiences) | B10: 0 | C10: 0 | D10: 0.15 | E10: 0.15 | F10: 0.18 | G10: 0.18 | H10: Deck puts "retarget people who viewed" in M3–4. Viewer pool from M1–2 ads is ready by then.
A11: Total (must be 100%) | B11: =SUM(B5:B10) | C11: =SUM(C5:C10) | D11: =SUM(D5:D10) | E11: =SUM(E5:E10) | F11: =SUM(F5:F10) | G11: =SUM(G5:G10)
A14: B. Campaign-wise budget (₹ per month) – total spend taken from your Media Planning sheet
A15: Campaign Name | B15: Share in type | C15: Month 1 | D15: Month 2 | E15: Month 3 | F15: Month 4 | G15: Month 5 | H15: Month 6 | I15: 6-month total | J15: Why this share
A16: Total monthly spend (Media Planning) | C16: ='Media Planning'!B5 | D16: ='Media Planning'!B6 | E16: ='Media Planning'!B7 | F16: ='Media Planning'!B8 | G16: ='Media Planning'!B9 | H16: ='Media Planning'!B10 | I16: =SUM(C16:H16)
A17: SP/ChettinadChicken/Brand KWs/Exact | B17: 0.08 | C17: =C$16*B$5*0.08 | D17: =D$16*C$5*0.08 | E17: =E$16*D$5*0.08 | F17: =F$16*E$5*0.08 | G17: =G$16*F$5*0.08 | H17: =H$16*G$5*0.08 | I17: =SUM(C17:H17) | J17: Brand search: curry it 2,400 + curryit 1,300 = 3,700/mo. Cheap; protect own name.
A18: SP/ChettinadChicken/Brand KWs/Phrase | B18: 0.05 | C18: =C$16*B$5*0.05 | D18: =D$16*C$5*0.05 | E18: =E$16*D$5*0.05 | F18: =F$16*E$5*0.05 | G18: =G$16*F$5*0.05 | H18: =H$16*G$5*0.05 | I18: =SUM(C18:H18) | J18: Catches "curryit chettinad…" variations.
A19: SP/ChettinadChicken/Brand KWs/Broad | B19: 0.02 | C19: =C$16*B$5*0.02 | D19: =D$16*C$5*0.02 | E19: =E$16*D$5*0.02 | F19: =F$16*E$5*0.02 | G19: =G$16*F$5*0.02 | H19: =H$16*G$5*0.02 | I19: =SUM(C19:H19) | J19: Small – only to find new brand terms.
A20: SP/ChettinadChicken/Generic KWs/Exact | B20: 0.3 | C20: =C$16*B$5*0.3 | D20: =D$16*C$5*0.3 | E20: =E$16*D$5*0.3 | F20: =F$16*E$5*0.3 | G20: =G$16*F$5*0.3 | H20: =H$16*G$5*0.3 | I20: =SUM(C20:H20) | J20: Main money bucket: Chettinad 1,980 + chicken curry masala 1,490 + paste/RTC 720 = 4,190 searches/mo. Deck: product keywords = Priority 1.
A21: SP/ChettinadChicken/Generic KWs/Phrase | B21: 0.2 | C21: =C$16*B$5*0.2 | D21: =D$16*C$5*0.2 | E21: =E$16*D$5*0.2 | F21: =F$16*E$5*0.2 | G21: =G$16*F$5*0.2 | H21: =H$16*G$5*0.2 | I21: =SUM(C21:H21) | J21: Same keywords, more search variations.
A22: SP/ChettinadChicken/Generic KWs/Broad | B22: 0.1 | C22: =C$16*B$5*0.1 | D22: =D$16*C$5*0.1 | E22: =E$16*D$5*0.1 | F22: =F$16*E$5*0.1 | G22: =G$16*F$5*0.1 | H22: =H$16*G$5*0.1 | I22: =SUM(C22:H22) | J22: Discovery only; negated vs Phrase.
A23: SP/ChettinadChicken/Comp KWs/Exact | B23: 0.12 | C23: =C$16*B$5*0.12 | D23: =D$16*C$5*0.12 | E23: =E$16*D$5*0.12 | F23: =F$16*E$5*0.12 | G23: =G$16*F$5*0.12 | H23: =H$16*G$5*0.12 | I23: =SUM(C23:H23) | J23: Comp keyword volume is small (Chettinad comp 230 + chicken masala brands 520 + paste brands 70 = 820/mo), and their buyers convert lower.
A24: SP/ChettinadChicken/Comp KWs/Phrase | B24: 0.08 | C24: =C$16*B$5*0.08 | D24: =D$16*C$5*0.08 | E24: =E$16*D$5*0.08 | F24: =F$16*E$5*0.08 | G24: =G$16*F$5*0.08 | H24: =H$16*G$5*0.08 | I24: =SUM(C24:H24) | J24: Same as above.
A25: SP/ChettinadChicken/Comp KWs/Broad | B25: 0.05 | C25: =C$16*B$5*0.05 | D25: =D$16*C$5*0.05 | E25: =E$16*D$5*0.05 | F25: =F$16*E$5*0.05 | G25: =G$16*F$5*0.05 | H25: =H$16*G$5*0.05 | I25: =SUM(C25:H25) | J25: Small test.
A26: SP/ChettinadChicken/Auto | B26: 1 | C26: =C$16*B$6*1.0 | D26: =D$16*C$6*1.0 | E26: =E$16*D$6*1.0 | F26: =F$16*E$6*1.0 | G26: =G$16*F$6*1.0 | H26: =H$16*G$6*1.0 | I26: =SUM(C26:H26) | J26: Only Auto campaign. Check search term report weekly (deck).
A27: SP/IP/CompTar (competitor ASINs) | B27: 0.55 | C27: =C$16*B$7*0.55 | D27: =D$16*C$7*0.55 | E27: =E$16*D$7*0.55 | F27: =F$16*E$7*0.55 | G27: =G$16*F$7*0.55 | H27: =H$16*G$7*0.55 | I27: =SUM(C27:H27) | J27: Show CURRYiT on competitor product pages (deck). Pitch: paste, ghee, no preservatives.
A28: SP/CT (category) | B28: 0.3 | C28: =C$16*B$7*0.3 | D28: =D$16*C$7*0.3 | E28: =E$16*D$7*0.3 | F28: =F$16*E$7*0.3 | G28: =G$16*F$7*0.3 | H28: =H$16*G$7*0.3 | I28: =SUM(C28:H28) | J28: Wider category reach at lower bid.
A29: SP/IP/BrandTar (own ASINs) | B29: 0.15 | C29: =C$16*B$7*0.15 | D29: =D$16*C$7*0.15 | E29: =E$16*D$7*0.15 | F29: =F$16*E$7*0.15 | G29: =G$16*F$7*0.15 | H29: =H$16*G$7*0.15 | I29: =SUM(C29:H29) | J29: Defend own pages, cross-sell other CURRYiT pastes.
A30: SB/Video/Brand kws-Exact | B30: 0.15 | C30: =C$16*B$8*0.15 | D30: =D$16*C$8*0.15 | E30: =E$16*D$8*0.15 | F30: =F$16*E$8*0.15 | G30: =G$16*F$8*0.15 | H30: =H$16*G$8*0.15 | I30: =SUM(C30:H30) | J30: Brand video for people already searching CURRYiT.
A31: SB/Video/Brand kws-Phrase | B31: 0.1 | C31: =C$16*B$8*0.1 | D31: =D$16*C$8*0.1 | E31: =E$16*D$8*0.1 | F31: =F$16*E$8*0.1 | G31: =G$16*F$8*0.1 | H31: =H$16*G$8*0.1 | I31: =SUM(C31:H31)
A32: SB/Video/Generic Chettinad kws-Exact | B32: 0.3 | C32: =C$16*B$8*0.3 | D32: =D$16*C$8*0.3 | E32: =E$16*D$8*0.3 | F32: =F$16*E$8*0.3 | G32: =G$16*F$8*0.3 | H32: =H$16*G$8*0.3 | I32: =SUM(C32:H32) | J32: Most new customers come from generic searches; video shows "15 mins, 3 steps".
A33: SB/Video/Generic Chettinad kws-Phrase | B33: 0.2 | C33: =C$16*B$8*0.2 | D33: =D$16*C$8*0.2 | E33: =E$16*D$8*0.2 | F33: =F$16*E$8*0.2 | G33: =G$16*F$8*0.2 | H33: =H$16*G$8*0.2 | I33: =SUM(C33:H33)
A34: SB/Video/Comp kws-Exact | B34: 0.15 | C34: =C$16*B$8*0.15 | D34: =D$16*C$8*0.15 | E34: =E$16*D$8*0.15 | F34: =F$16*E$8*0.15 | G34: =G$16*F$8*0.15 | H34: =H$16*G$8*0.15 | I34: =SUM(C34:H34) | J34: Steal comp searches with the video.
A35: SB/Video/Comp kws-Phrase | B35: 0.1 | C35: =C$16*B$8*0.1 | D35: =D$16*C$8*0.1 | E35: =E$16*D$8*0.1 | F35: =F$16*E$8*0.1 | G35: =G$16*F$8*0.1 | H35: =H$16*G$8*0.1 | I35: =SUM(C35:H35)
A36: SB Brand – Product Collection (Combo-3) – ADD from M3 | B36: 1 | C36: =C$16*B$9*1.0 | D36: =D$16*C$9*1.0 | E36: =E$16*D$9*1.0 | F36: =F$16*E$9*1.0 | G36: =G$16*F$9*1.0 | H36: =H$16*G$9*1.0 | I36: =SUM(C36:H36) | J36: Not in your SB sheet yet. Deck: SB Brand starts M3 and sells the combo (AOV ₹450).
A37: SD/Remarketing/Views | B37: 40% (M3–4) / 35% (M5–6) | C37: =C$16*B$10*0.4 | D37: =D$16*C$10*0.4 | E37: =E$16*D$10*0.4 | F37: =F$16*E$10*0.4 | G37: =G$16*F$10*0.35 | H37: =H$16*G$10*0.35 | I37: =SUM(C37:H37) | J37: Warmest audience: saw the pack, did not buy. Deck: "retarget people who viewed".
A38: SD/Remarketing/Purchases | B38: 10% (M3–4) / 20% (M5–6) | C38: =C$16*B$10*0.1 | D38: =D$16*C$10*0.1 | E38: =E$16*D$10*0.1 | F38: =F$16*E$10*0.1 | G38: =G$16*F$10*0.2 | H38: =H$16*G$10*0.2 | I38: =SUM(C38:H38) | J38: Grows in M5–6: deck says "repeat buyers add up". One pouch = one meal, so rebuy is natural.
A39: SD/Contextual/IP (comp ASINs) | B39: 20% (M3–4) / 15% (M5–6) | C39: =C$16*B$10*0.2 | D39: =D$16*C$10*0.2 | E39: =E$16*D$10*0.2 | F39: =F$16*E$10*0.2 | G39: =G$16*F$10*0.15 | H39: =H$16*G$10*0.15 | I39: =SUM(C39:H39) | J39: Same comp ASINs as SP IP, cheaper display placement.
A40: SD/Contextual/CT | B40: 15% (M3–4) / 10% (M5–6) | C40: =C$16*B$10*0.15 | D40: =D$16*C$10*0.15 | E40: =E$16*D$10*0.15 | F40: =F$16*E$10*0.15 | G40: =G$16*F$10*0.1 | H40: =H$16*G$10*0.1 | I40: =SUM(C40:H40) | J40: Category pages; cut in M5–6 (tighten, do not expand).
A41: SD/Inmarketing | B41: 10% (M3–4) / 15% (M5–6) | C41: =C$16*B$10*0.1 | D41: =D$16*C$10*0.1 | E41: =E$16*D$10*0.1 | F41: =F$16*E$10*0.1 | G41: =G$16*F$10*0.15 | H41: =H$16*G$10*0.15 | I41: =SUM(C41:H41) | J41: New shoppers already buying spices/pastes.
A42: SD/Contextual/IP (own ASINs) | B42: 5% (M3–4) / 5% (M5–6) | C42: =C$16*B$10*0.05 | D42: =D$16*C$10*0.05 | E42: =E$16*D$10*0.05 | F42: =F$16*E$10*0.05 | G42: =G$16*F$10*0.05 | H42: =H$16*G$10*0.05 | I42: =SUM(C42:H42) | J42: Small defence on own pages.
A43: Total (must match monthly spend) | C43: =SUM(C17:C42) | D43: =SUM(D17:D42) | E43: =SUM(E17:E42) | F43: =SUM(F17:F42) | G43: =SUM(G17:G42) | H43: =SUM(H17:H42) | I43: =SUM(I17:I42)
...
