Workbook
Name AOV: 'Media Planning'!$M$5

Sheet All keywords
A1: Keyword | B1: Avg. monthly searches | C1: Relevant | D1: Broader/Campaign | E1: Sub Theme/Adgroup | F1: Reason | G1: Category | H1: Intent
A2: curry paste thai | B2: 3600 | C2: No | F2: Thai / foreign cuisine – wrong flavour for a Chettinad paste | G2: Generic | H2: High / Commercial
A3: thai curry paste | B3: 3600 | C3: No | F3: Thai / foreign cuisine – wrong flavour for a Chettinad paste | G3: Generic | H3: High / Commercial
A4: thai green curry paste | B4: 2900 | C4: No | F4: Thai / foreign cuisine – wrong flavour for a Chettinad paste | G4: Generic | H4: High / Commercial
A5: thai red curry paste | B5: 2400 | C5: No | F5: Thai / foreign cuisine – wrong flavour for a Chettinad paste | G5: Generic | H5: High / Commercial
A6: chicken curry masala | B6: 1300 | C6: Yes | D6: Generic | E6: Chicken Curry Masala | F6: Same cooking need (chicken curry) | G6: Generic | H6: High / Commercial
A7: chettinad masala | B7: 1000 | C7: Yes | D7: Generic | E7: Chettinad | F7: Exact cuisine match | G7: Generic | H7: High / Commercial
A8: chicken chettinad masala | B8: 720 | C8: Yes | D8: Generic | E8: Chettinad | F8: Exact cuisine match | G8: Generic | H8: High / Commercial
A9: red curry paste | B9: 720 | C9: No | F9: Thai / foreign cuisine – wrong flavour for a Chettinad paste | G9: Generic | H9: High / Commercial
A10: green curry paste | B10: 590 | C10: No | F10: Thai / foreign cuisine – wrong flavour for a Chettinad paste | G10: Generic | H10: High / Commercial
A11: real thai red curry paste | B11: 590 | C11: No | F11: Thai / foreign cuisine – wrong flavour for a Chettinad paste | G11: Generic | H11: High / Commercial
A12: mae ploy thai curry paste | B12: 480 | C12: No | F12: Thai / foreign cuisine – wrong flavour for a Chettinad paste | G12: Competitor | H12: High / Commercial
A13: massaman curry paste | B13: 480 | C13: No | F13: Thai / foreign cuisine – wrong flavour for a Chettinad paste | G13: Generic | H13: High / Commercial
A14: curry paste | B14: 390 | C14: Yes | D14: Generic | E14: Curry Paste / Ready to Cook | F14: Format match (paste / ready-to-cook) | G14: Generic | H14: High / Commercial
A15: real thai green curry paste | B15: 390 | C15: No | F15: Thai / foreign cuisine – wrong flavour for a Chettinad paste | G15: Generic | H15: High / Commercial
A16: thai yellow curry paste | B16: 320 | C16: No | F16: Thai / foreign cuisine – wrong flavour for a Chettinad paste | G16: Generic | H16: High / Commercial
A17: yellow curry paste | B17: 260 | C17: No | F17: Thai / foreign cuisine – wrong flavour for a Chettinad paste | G17: Generic | H17: High / Commercial
A18: chicken curry masala powder | B18: 170 | C18: Yes | D18: Generic | E18: Chicken Curry Masala | F18: Same cooking need (chicken curry) | G18: Generic | H18: High / Commercial
A19: maesri thai curry paste | B19: 170 | C19: No | F19: Thai / foreign cuisine – wrong flavour for a Chettinad paste | G19: Generic | H19: High / Commercial
A20: namjai green curry paste | B20: 170 | C20: No | F20: Thai / foreign cuisine – wrong flavour for a Chettinad paste | G20: Generic | H20: High / Commercial
A21: real thai curry paste | B21: 170 | C21: No | F21: Thai / foreign cuisine – wrong flavour for a Chettinad paste | G21: Generic | H21: High / Commercial
A22: thai kitchen red curry paste | B22: 170 | C22: No | F22: Thai / foreign cuisine – wrong flavour for a Chettinad paste | G22: Competitor | H22: High / Commercial
A23: chettinad masala powder | B23: 140 | C23: Yes | D23: Generic | E23: Chettinad | F23: Exact cuisine match | G23: Generic | H23: High / Commercial
A24: mdh chicken curry masala | B24: 140 | C24: Yes | D24: Competitor | E24: Chicken Curry Masala Brands | F24: Competitor brand, chicken curry masala | G24: Competitor | H24: High / Commercial
A25: sunrise chicken curry masala | B25: 140 | C25: Yes | D25: Competitor | E25: Chicken Curry Masala Brands | F25: Competitor brand, chicken curry masala | G25: Generic | H25: High / Commercial
A26: chettinad chicken masala powder | B26: 110 | C26: Yes | D26: Generic | E26: Chettinad | F26: Exact cuisine match | G26: Generic | H26: High / Commercial
A27: cookd chettinad masala | B27: 110 | C27: Yes | D27: Competitor | E27: Chettinad Competitors | F27: Competitor brand + Chettinad | G27: Generic | H27: High / Commercial
A28: curry leaves paste | B28: 110 | C28: No | F28: Single-ingredient paste, not a curry | G28: Generic | H28: High / Commercial
A29: blue elephant curry paste | B29: 90 | C29: No | F29: Thai / foreign cuisine – wrong flavour for a Chettinad paste | G29: Competitor | H29: High / Commercial
A30: blue elephant thai curry paste | B30: 90 | C30: No | F30: Thai / foreign cuisine – wrong flavour for a Chettinad paste | G30: Competitor | H30: High / Commercial
A31: chettinad biryani masala | B31: 90 | C31: No | F31: Biryani – different dish | G31: Generic | H31: High / Commercial
A32: curry it ginger garlic paste | B32: 90 | C32: No | F32: Own brand, other product – route to that product's campaign | G32: Brand | H32: High / Commercial
A33: curry paste indian | B33: 90 | C33: Yes | D33: Generic | E33: Curry Paste / Ready to Cook | F33: Format match (paste / ready-to-cook) | G33: Generic | H33: High / Commercial
A34: namjai red curry paste | B34: 90 | C34: No | F34: Thai / foreign cuisine – wrong flavour for a Chettinad paste | G34: Generic | H34: High / Commercial
A35: real thai yellow curry paste | B35: 90 | C35: No | F35: Thai / foreign cuisine – wrong flavour for a Chettinad paste | G35: Generic | H35: High / Commercial
A36: suhana chicken curry masala | B36: 90 | C36: Yes | D36: Competitor | E36: Chicken Curry Masala Brands | F36: Competitor brand, chicken curry masala | G36: Competitor | H36: High / Commercial
A37: jain thai curry paste | B37: 70 | C37: No | F37: Jain / no onion-garlic; CURRYiT contains onion & garlic | G37: Generic | H37: High / Commercial
A38: katsu curry paste | B38: 70 | C38: No | F38: Thai / foreign cuisine – wrong flavour for a Chettinad paste | G38: Generic | H38: High / Commercial
A39: knorr thai curry paste | B39: 70 | C39: No | F39: Thai / foreign cuisine – wrong flavour for a Chettinad paste | G39: Competitor | H39: High / Commercial
A40: namjai curry paste | B40: 70 | C40: No | F40: Thai / foreign cuisine – wrong flavour for a Chettinad paste | G40: Generic | H40: High / Commercial
...

Sheet Generic Kws
A1: Keyword | B1: Avg. monthly searches | C1: Relevant | D1: Broader/Campaign | E1: Sub Theme/Adgroup | F1: Reason | G1: Category | H1: Intent
A2: curry paste thai | B2: 3600 | C2: No | F2: Thai / foreign cuisine – wrong flavour for a Chettinad paste | G2: Generic | H2: High / Commercial
A3: thai curry paste | B3: 3600 | C3: No | F3: Thai / foreign cuisine – wrong flavour for a Chettinad paste | G3: Generic | H3: High / Commercial
A4: thai green curry paste | B4: 2900 | C4: No | F4: Thai / foreign cuisine – wrong flavour for a Chettinad paste | G4: Generic | H4: High / Commercial
A5: thai red curry paste | B5: 2400 | C5: No | F5: Thai / foreign cuisine – wrong flavour for a Chettinad paste | G5: Generic | H5: High / Commercial
A6: chicken curry masala | B6: 1300 | C6: Yes | D6: Generic | E6: Chicken Curry Masala | F6: Same cooking need (chicken curry) | G6: Generic | H6: High / Commercial
A7: chettinad masala | B7: 1000 | C7: Yes | D7: Generic | E7: Chettinad | F7: Exact cuisine match | G7: Generic | H7: High / Commercial
A8: chicken chettinad masala | B8: 720 | C8: Yes | D8: Generic | E8: Chettinad | F8: Exact cuisine match | G8: Generic | H8: High / Commercial
A9: red curry paste | B9: 720 | C9: No | F9: Thai / foreign cuisine – wrong flavour for a Chettinad paste | G9: Generic | H9: High / Commercial
A10: green curry paste | B10: 590 | C10: No | F10: Thai / foreign cuisine – wrong flavour for a Chettinad paste | G10: Generic | H10: High / Commercial
A11: real thai red curry paste | B11: 590 | C11: No | F11: Thai / foreign cuisine – wrong flavour for a Chettinad paste | G11: Generic | H11: High / Commercial
A12: massaman curry paste | B12: 480 | C12: No | F12: Thai / foreign cuisine – wrong flavour for a Chettinad paste | G12: Generic | H12: High / Commercial
A13: curry paste | B13: 390 | C13: Yes | D13: Generic | E13: Curry Paste / Ready to Cook | F13: Format match (paste / ready-to-cook) | G13: Generic | H13: High / Commercial
A14: real thai green curry paste | B14: 390 | C14: No | F14: Thai / foreign cuisine – wrong flavour for a Chettinad paste | G14: Generic | H14: High / Commercial
A15: thai yellow curry paste | B15: 320 | C15: No | F15: Thai / foreign cuisine – wrong flavour for a Chettinad paste | G15: Generic | H15: High / Commercial
A16: yellow curry paste | B16: 260 | C16: No | F16: Thai / foreign cuisine – wrong flavour for a Chettinad paste | G16: Generic | H16: High / Commercial
A17: chicken curry masala powder | B17: 170 | C17: Yes | D17: Generic | E17: Chicken Curry Masala | F17: Same cooking need (chicken curry) | G17: Generic | H17: High / Commercial
A18: maesri thai curry paste | B18: 170 | C18: No | F18: Thai / foreign cuisine – wrong flavour for a Chettinad paste | G18: Generic | H18: High / Commercial
A19: namjai green curry paste | B19: 170 | C19: No | F19: Thai / foreign cuisine – wrong flavour for a Chettinad paste | G19: Generic | H19: High / Commercial
A20: real thai curry paste | B20: 170 | C20: No | F20: Thai / foreign cuisine – wrong flavour for a Chettinad paste | G20: Generic | H20: High / Commercial
A21: chettinad masala powder | B21: 140 | C21: Yes | D21: Generic | E21: Chettinad | F21: Exact cuisine match | G21: Generic | H21: High / Commercial
A22: sunrise chicken curry masala | B22: 140 | C22: Yes | D22: Competitor | E22: Chicken Curry Masala Brands | F22: Competitor brand, chicken curry masala | G22: Generic | H22: High / Commercial
A23: chettinad chicken masala powder | B23: 110 | C23: Yes | D23: Generic | E23: Chettinad | F23: Exact cuisine match | G23: Generic | H23: High / Commercial
A24: cookd chettinad masala | B24: 110 | C24: Yes | D24: Competitor | E24: Chettinad Competitors | F24: Competitor brand + Chettinad | G24: Generic | H24: High / Commercial
A25: curry leaves paste | B25: 110 | C25: No | F25: Single-ingredient paste, not a curry | G25: Generic | H25: High / Commercial
A26: chettinad biryani masala | B26: 90 | C26: No | F26: Biryani – different dish | G26: Generic | H26: High / Commercial
A27: curry paste indian | B27: 90 | C27: Yes | D27: Generic | E27: Curry Paste / Ready to Cook | F27: Format match (paste / ready-to-cook) | G27: Generic | H27: High / Commercial
A28: namjai red curry paste | B28: 90 | C28: No | F28: Thai / foreign cuisine – wrong flavour for a Chettinad paste | G28: Generic | H28: High / Commercial
A29: real thai yellow curry paste | B29: 90 | C29: No | F29: Thai / foreign cuisine – wrong flavour for a Chettinad paste | G29: Generic | H29: High / Commercial
A30: jain thai curry paste | B30: 70 | C30: No | F30: Jain / no onion-garlic; CURRYiT contains onion & garlic | G30: Generic | H30: High / Commercial
A31: katsu curry paste | B31: 70 | C31: No | F31: Thai / foreign cuisine – wrong flavour for a Chettinad paste | G31: Generic | H31: High / Commercial
A32: namjai curry paste | B32: 70 | C32: No | F32: Thai / foreign cuisine – wrong flavour for a Chettinad paste | G32: Generic | H32: High / Commercial
A33: namjai thai curry paste | B33: 70 | C33: No | F33: Thai / foreign cuisine – wrong flavour for a Chettinad paste | G33: Generic | H33: High / Commercial
A34: non veg curry masala paste | B34: 70 | C34: Yes | D34: Generic | E34: Curry Paste / Ready to Cook | F34: Format match (paste / ready-to-cook) | G34: Generic | H34: High / Commercial
A35: sakthi chettinad chicken masala | B35: 70 | C35: Yes | D35: Competitor | E35: Chettinad Competitors | F35: Competitor brand + Chettinad | G35: Generic | H35: High / Commercial
A36: laksa curry paste | B36: 50 | C36: No | F36: Thai / foreign cuisine – wrong flavour for a Chettinad paste | G36: Generic | H36: High / Commercial
A37: rendang curry paste | B37: 50 | C37: No | F37: Thai / foreign cuisine – wrong flavour for a Chettinad paste | G37: Generic | H37: High / Commercial
A38: thai green curry paste vegetarian | B38: 50 | C38: No | F38: Thai / foreign cuisine – wrong flavour for a Chettinad paste | G38: Generic | H38: High / Commercial
A39: zoff chicken curry masala | B39: 50 | C39: Yes | D39: Competitor | E39: Chicken Curry Masala Brands | F39: Competitor brand, chicken curry masala | G39: Generic | H39: High / Commercial
A40: fish curry paste | B40: 40 | C40: No | F40: Other dish / other CURRYiT product – route elsewhere | G40: Generic | H40: High / Commercial
...

Sheet Brand Kws
A1: Keyword | B1: Avg. monthly searches | C1: Relevant | D1: Broader/Campaign | E1: Sub Theme/Adgroup | F1: Reason | G1: Category | H1: Intent
A2: curry it ginger garlic paste | B2: 90 | C2: No | F2: Own brand, other product – route to that product's campaign | G2: Brand | H2: High / Commercial
A3: curryit chettinad chicken curry masala paste | C3: Yes | D3: Brand | E3: Brand + Chettinad | F3: Own brand + exact product | G3: Brand | H3: High / Commercial
A4: curryit punjabi kadhai paneer masala premium cooking paste | C4: No | F4: Own brand, other product – route to that product's campaign | G4: Brand | H4: High / Commercial
A5: curryit | B5: 1300 | D5: Brand | E5: Brand | F5: Brand keyword – directly searches for CURRYiT | G5: Brand | H5: Generic / Mixed
A6: Curryit paste | D6: Brand | E6: Brand | F6: Brand keyword – directly searches for CURRYiT paste | G6: Brand | H6: High / Commercial
A7: curry it | B7: 2400 | D7: Brand | E7: Brand | F7: Brand keyword – alternate spelling of CURRYiT | G7: Brand | H7: Generic / Mixed

Sheet Comp Keywords
A1: Keyword | B1: Avg. monthly searches | C1: Relevant | D1: Broader/Campaign | E1: Sub Theme/Adgroup | F1: Reason | G1: Category | H1: Intent
A2: mae ploy thai curry paste | B2: 480 | C2: No | F2: Thai / foreign cuisine – wrong flavour for a Chettinad paste | G2: Competitor | H2: High / Commercial
A3: thai kitchen red curry paste | B3: 170 | C3: No | F3: Thai / foreign cuisine – wrong flavour for a Chettinad paste | G3: Competitor | H3: High / Commercial
A4: mdh chicken curry masala | B4: 140 | C4: Yes | D4: Competitor | E4: Chicken Curry Masala Brands | F4: Competitor brand, chicken curry masala | G4: Competitor | H4: High / Commercial
A5: blue elephant curry paste | B5: 90 | C5: No | F5: Thai / foreign cuisine – wrong flavour for a Chettinad paste | G5: Competitor | H5: High / Commercial
A6: blue elephant thai curry paste | B6: 90 | C6: No | F6: Thai / foreign cuisine – wrong flavour for a Chettinad paste | G6: Competitor | H6: High / Commercial
A7: suhana chicken curry masala | B7: 90 | C7: Yes | D7: Competitor | E7: Chicken Curry Masala Brands | F7: Competitor brand, chicken curry masala | G7: Competitor | H7: High / Commercial
A8: knorr thai curry paste | B8: 70 | C8: No | F8: Thai / foreign cuisine – wrong flavour for a Chettinad paste | G8: Competitor | H8: High / Commercial
A9: everest chicken curry masala | B9: 50 | C9: Yes | D9: Competitor | E9: Chicken Curry Masala Brands | F9: Competitor brand, chicken curry masala | G9: Competitor | H9: High / Commercial
A10: thai kitchen green curry paste | B10: 50 | C10: No | F10: Thai / foreign cuisine – wrong flavour for a Chettinad paste | G10: Competitor | H10: High / Commercial
A11: knorr green thai curry paste | B11: 40 | C11: No | F11: Thai / foreign cuisine – wrong flavour for a Chettinad paste | G11: Competitor | H11: High / Commercial
A12: aachi chicken curry masala | B12: 30 | C12: Yes | D12: Competitor | E12: Chicken Curry Masala Brands | F12: Competitor brand, chicken curry masala | G12: Competitor | H12: High / Commercial
A13: aachi curry leaf rice paste | B13: 30 | C13: No | F13: Pack size / diet / unrelated product | G13: Competitor | H13: High / Commercial
A14: blue elephant green curry paste | B14: 30 | C14: No | F14: Thai / foreign cuisine – wrong flavour for a Chettinad paste | G14: Competitor | H14: High / Commercial
A15: blue elephant thai green curry paste | B15: 30 | C15: No | F15: Thai / foreign cuisine – wrong flavour for a Chettinad paste | G15: Competitor | H15: High / Commercial
A16: itc master chef butter chicken cooking paste | B16: 30 | C16: No | F16: Other dish / other CURRYiT product – route elsewhere | G16: Competitor | H16: High / Commercial
A17: aachi chettinad chicken biryani masala | B17: 20 | C17: No | F17: Biryani – different dish | G17: Competitor | H17: High / Commercial
A18: itc cooking paste | B18: 20 | C18: Yes | D18: Competitor | E18: Cooking Paste Brands | F18: Competitor brand, same paste format | G18: Competitor | H18: High / Commercial
A19: itc master chef cooking paste | B19: 20 | C19: Yes | D19: Competitor | E19: Cooking Paste Brands | F19: Competitor brand, same paste format | G19: Competitor | H19: High / Commercial
A20: priya non veg curry masala paste | B20: 20 | C20: Yes | D20: Competitor | E20: Cooking Paste Brands | F20: Competitor brand, same paste format | G20: Competitor | H20: High / Commercial
A21: aachi chettinad chicken masala | B21: 10 | C21: Yes | D21: Competitor | E21: Chettinad Competitors | F21: Competitor brand + Chettinad | G21: Competitor | H21: High / Commercial
A22: blue elephant red thai curry paste | B22: 10 | C22: No | F22: Thai / foreign cuisine – wrong flavour for a Chettinad paste | G22: Competitor | H22: High / Commercial
A23: itc masterchef cooking paste | B23: 10 | C23: Yes | D23: Competitor | E23: Cooking Paste Brands | F23: Competitor brand, same paste format | G23: Competitor | H23: High / Commercial
A24: shan chicken curry masala | B24: 10 | C24: Yes | D24: Competitor | E24: Chicken Curry Masala Brands | F24: Competitor brand, chicken curry masala | G24: Competitor | H24: High / Commercial
A25: aachi chettinad masala | C25: Yes | D25: Competitor | E25: Chettinad Competitors | F25: Competitor brand + Chettinad | G25: Competitor | H25: High / Commercial
A26: chettinad masala mtr | C26: Yes | D26: Competitor | E26: Chettinad Competitors | F26: Competitor brand + Chettinad | G26: Competitor | H26: High / Commercial
A27: itc butter chicken cooking paste | C27: No | F27: Other dish / other CURRYiT product – route elsewhere | G27: Competitor | H27: High / Commercial
A28: itc curry paste | C28: Yes | D28: Competitor | E28: Cooking Paste Brands | F28: Competitor brand, same paste format | G28: Competitor | H28: High / Commercial
A29: mother's recipe chicken curry masala | C29: Yes | D29: Competitor | E29: Chicken Curry Masala Brands | F29: Competitor brand, chicken curry masala | G29: Competitor | H29: High / Commercial
A30: mothers recipe chicken chettinad masala | C30: Yes | D30: Competitor | E30: Chettinad Competitors | F30: Competitor brand + Chettinad | G30: Competitor | H30: High / Commercial
A31: saffola masala oats chicken curry flavour | C31: No | F31: Pack size / diet / unrelated product | G31: Competitor | H31: High / Commercial
A32: tata sampann chicken curry masala | C32: Yes | D32: Competitor | E32: Chicken Curry Masala Brands | F32: Competitor brand, chicken curry masala | G32: Competitor | H32: High / Commercial

Sheet SP Campaign
B1: SPONSERED Product – Chettinad Chicken Curry Paste
A2: ASIN- B0G1YXWM2P
A4: Campaign Objective | B4: Campaign Name | C4: Ad grp Name | D4: Bidding Strategy | E4: Advertised Product | F4: Targetting | G4: Negative Targetting
B5: Auto
A7: Conversion | B7: SP/ChettinadChicken /Auto | C7: ChettinadChicken-Auto | D7: Down only | E7: B0G1YXWM2P | F7: - Close - Loose - Substitute - Complements | G7: Negate in Exact: curry it curryit chicken curry masala chettinad masala chicken chettinad masala curry paste chicken curry masala powder chettinad masala powder chicken curry masala chettinad chicken masala powder cookd chettinad masala curry paste indian non veg curry masala paste sakthi chettinad chicken masala zoff chicken curry masala ready to cook curry mutton curry paste ready to cook chicken curry cooking pastes india gate chettinad chicken masala india gate classic chettinad chicken masala ready to cook curry paste mdh chicken curry masala suhana chicken curry masala everest chicken curry masala aachi chicken curry masala itc cooking paste itc master chef cooking paste priya non veg curry masala paste aachi chettinad chicken masala itc masterchef cooking paste shan chicken curry masala Negate Product: B079H3DFP7 B0FLP9NYR1 B07BH4B384 B08MFLHMJC B0CY8KKGGP B09BD5VW64 B09BD5BNJ7 B0917NY7X6 B09BD583S6 B08H284SNC B0777JV82Z B0BV76DCY6 B0DPJ3P467 B0C53VBXVM B0BV7783X7 B0C58S9P1K B0G1YZ3K4T B0G1Z87RV9 B0CL9D1PHY B0G1YZ5K91
B9: Brand KW
A10: Conversion | B10: SP/ChettinadChicken/Brand KWs/Exact | C10: ChettinadChicken-Brand Kws- Exact | D10: Up and Down | E10: B0G1YXWM2P | F10: curry it curryit | G10: NA
A12: Conversion | B12: SP/ChettinadChicken/Brand KWs/Phrase | C12: ChettinadChicken-Brand Kws- Phrase | D12: Up and Down | E12: B0G1YXWM2P | F12: curry it curryit | G12: Negate In EXACT curry it curryit
A14: Conversion | B14: SP/ChettinadChicken/Brand KWs/Broad | C14: ChettinadChicken-Brand Kws- Broad | D14: Down Only | E14: B0G1YXWM2P | F14: curry it curryit | G14: Negate In Phrase curry it curryit
B16: Generic KWS
A17: Conversion | B17: SP/ChettinadChicken/Generic KWs/Exact | C17: ChettinadChicken-Geneirc Kws- Exact | D17: Up and Down | E17: B0G1YXWM2P | F17: chicken curry masala chettinad masala chicken chettinad masala curry paste chicken curry masala powder chettinad masala powder chicken curry masala chettinad chicken masala powder cookd chettinad masala curry paste indian non veg curry masala paste ready to cook curry mutton curry paste ready to cook chicken curry cooking pastes ready to cook curry paste | G17: NA
A19: Conversion | B19: SP/ChettinadChicken/Generic KWs/Phrase | C19: ChettinadChicken-Geneirc Kws- Phrase | D19: Up and Down | E19: B0G1YXWM2P | F19: chicken curry masala chettinad masala chicken chettinad masala curry paste chicken curry masala powder chettinad masala powder chicken curry masala chettinad chicken masala powder cookd chettinad masala curry paste indian non veg curry masala paste ready to cook curry mutton curry paste ready to cook chicken curry cooking pastes ready to cook curry paste | G19: Negate in exact- chicken curry masala chettinad masala chicken chettinad masala curry paste chicken curry masala powder chettinad masala powder chicken curry masala chettinad chicken masala powder cookd chettinad masala curry paste indian non veg curry masala paste ready to cook curry mutton curry paste ready to cook chicken curry cooking pastes ready to cook curry paste
A21: Conversion | B21: SP/ChettinadChicken/Generic KWs/Broad | C21: ChettinadChicken-Geneirc Kws- Broad | D21: Down Only | E21: B0G1YXWM2P | F21: chicken curry masala chettinad masala chicken chettinad masala curry paste chicken curry masala powder chettinad masala powder chicken curry masala chettinad chicken masala powder cookd chettinad masala curry paste indian non veg curry masala paste ready to cook curry mutton curry paste ready to cook chicken curry cooking pastes ready to cook curry paste | G21: Negate in Phrase- chicken curry masala chettinad masala chicken chettinad masala curry paste chicken curry masala powder chettinad masala powder chicken curry masala chettinad chicken masala powder cookd chettinad masala curry paste indian non veg curry masala paste ready to cook curry mutton curry paste ready to cook chicken curry cooking pastes ready to cook curry paste
B23: Competitiors Kws
A25: Consideration/ Awarness | B25: SP/ChettinadChicken/Comp KWs/Exact | C25: ChettinadChicken-Comp Kws- Exact | D25: Down Only | E25: B0G1YXWM2P | F25: mdh chicken curry masala suhana chicken curry masala everest chicken curry masala aachi chicken curry masala itc cooking paste itc master chef cooking paste priya non veg curry masala paste aachi chettinad chicken masala itc masterchef cooking paste shan chicken curry masala | G25: NA
A27: Consideration/ Awarness | B27: SP/ChettinadChicken/Comp KWs/Phrase | C27: ChettinadChicken-Comp Kws- Phrase | D27: Down Only | E27: B0G1YXWM2P | F27: mdh chicken curry masala suhana chicken curry masala everest chicken curry masala aachi chicken curry masala itc cooking paste itc master chef cooking paste priya non veg curry masala paste aachi chettinad chicken masala itc masterchef cooking paste shan chicken curry masala | G27: Negate in exact- mdh chicken curry masala suhana chicken curry masala everest chicken curry masala aachi chicken curry masala itc cooking paste itc master chef cooking paste priya non veg curry masala paste aachi chettinad chicken masala itc masterchef cooking paste shan chicken curry masala
A29: Consideration/ Awarness | B29: SP/ChettinadChicken/Comp KWs/Broad | C29: ChettinadChicken-Comp Kws- Broad | D29: Down Only | E29: B0G1YXWM2P | F29: mdh chicken curry masala suhana chicken curry masala everest chicken curry masala aachi chicken curry masala itc cooking paste itc master chef cooking paste priya non veg curry masala paste aachi chettinad chicken masala itc masterchef cooking paste shan chicken curry masala | G29: Negate in Phrase- mdh chicken curry masala suhana chicken curry masala everest chicken curry masala aachi chicken curry masala itc cooking paste itc master chef cooking paste priya non veg curry masala paste aachi chettinad chicken masala itc masterchef cooking paste shan chicken curry masala
B31: Category
A33: Awareness | B33: SP/Whey Protein/CT | C33: ChettinadChicken- CT | D33: Down Only | E33: B0G1YXWM2P | F33: Cooking & Baking Supplies›Spices & Masalas›Powdered Spices, Seasonings & Masalas›Mixed Spices & Seasonings›Ready Masalas & Curry Powder | G33: Negate in exact- B079H3DFP7 B0FLP9NYR1 B07BH4B384 B08MFLHMJC B0CY8KKGGP B09BD5VW64 B09BD5BNJ7 B0917NY7X6 B09BD583S6 B08H284SNC B0777JV82Z B0BV76DCY6 B0DPJ3P467 B0C53VBXVM B0BV7783X7 B0C58S9P1K
B35: Individual
A37: Consideration | B37: SP/Whey Protein/IP/CompTar | C37: ChettinadChicken- IP | D37: Down Only | E37: B0G1YXWM2P | F37: B079H3DFP7 B0FLP9NYR1 B07BH4B384 B08MFLHMJC B0CY8KKGGP B09BD5VW64 B09BD5BNJ7 B0917NY7X6 B09BD583S6 B08H284SNC B0777JV82Z B0BV76DCY6 B0DPJ3P467 B0C53VBXVM B0BV7783X7 B0C58S9P1K | G37: NA
A39: Conversion | B39: SP/Whey Protein/IP/BrandTar | C39: ChettinadChicken- IP | D39: Down Only | E39: B0G1YXWM2P | F39: B0G1YZ3K4T B0G1Z87RV9 B0CL9D1PHY B0G1YZ5K91 | G39: NA

Sheet SB Campaign
B1: SPONSERED BRAND (SB) – ChettinadChicken Chettinad Chicken Curry Paste
A2: Campaign Objective | B2: Campaign Name | C2: Ad grp Name | D2: Advertised Product | E2: Ad Format | F2: Targeting | G2: Negative Targeting
A3: Conversion | B3: SB/ChettinadChicken/Video/Brand kws-Exact | C3: Video - Brand Exact | D3: B0G1YXWM2P | E3: Video | F3: curry it curryit | G3: N/A
A7: Conversion | B7: SB/ChettinadChicken/Video/Brand kws-Pharse | C7: Video - Brand Pharse | D7: B0G1YXWM2P | E7: Video | F7: curry it curryit | G7: Negate in Exact curry it curryit
A12: Conversion | B12: SB/ChettinadChicken/Video/Generic Chettinad kws-Exact | C12: Video - Chettinad Exact | D12: B0G1YXWM2P | E12: Video | F12: chicken curry masala chettinad masala chicken chettinad masala curry paste chicken curry masala powder chettinad masala powder chicken curry masala chettinad chicken masala powder cookd chettinad masala curry paste indian non veg curry masala paste ready to cook curry mutton curry paste ready to cook chicken curry cooking pastes ready to cook curry paste | G12: N/A
A19: Conversion/ Awarenss | B19: SB/ChettinadChicken/Video/Generic Chettinad kws-Pharse | C19: Video - Chettinad Pharse | D19: B0G1YXWM2P | E19: Video | F19: chicken curry masala chettinad masala chicken chettinad masala curry paste chicken curry masala powder chettinad masala powder chicken curry masala chettinad chicken masala powder cookd chettinad masala curry paste indian non veg curry masala paste ready to cook curry mutton curry paste ready to cook chicken curry cooking pastes ready to cook curry paste | G19: Negate in Exact chicken curry masala chettinad masala chicken chettinad masala curry paste chicken curry masala powder chettinad masala powder chicken curry masala chettinad chicken masala powder cookd chettinad masala curry paste indian non veg curry masala paste ready to cook curry mutton curry paste ready to cook chicken curry cooking pastes ready to cook curry paste
A27: Consideration/ Awareness | B27: SB/ChettinadChicken/Video/Comp Chettinad kws-Exact | C27: Video - Comp Chettinad Exact | D27: B0G1YXWM2P | E27: Video | F27: mdh chicken curry masala suhana chicken curry masala everest chicken curry masala aachi chicken curry masala itc cooking paste itc master chef cooking paste priya non veg curry masala paste aachi chettinad chicken masala itc masterchef cooking paste shan chicken curry masala | G27: N/A
A38: Consideration/ Awareness | B38: SB/ChettinadChicken/Video/Comp Chettinad kws-Pharse | C38: Video - Comp Chettinad Pharse | D38: B0G1YXWM2P | E38: Video | F38: mdh chicken curry masala suhana chicken curry masala everest chicken curry masala aachi chicken curry masala itc cooking paste itc master chef cooking paste priya non veg curry masala paste aachi chettinad chicken masala itc masterchef cooking paste shan chicken curry masala | G38: Negate in Exact mdh chicken curry masala suhana chicken curry masala everest chicken curry masala aachi chicken curry masala itc cooking paste itc master chef cooking paste priya non veg curry masala paste aachi chettinad chicken masala itc masterchef cooking paste shan chicken curry masala

Sheet SD Campaign
B1: SPONSORED DISPLAY (SD) – Contextual Chettinad Chicken Curry Paste
B2: Campaign Name | C2: Ad grp Name | D2: Ad Format | E2: Advertised Product | F2: Targeting
A3: Consideration | B3: SD/Chettinad Chicken/Contextual/IP | C3: Chettinad Paste/Contextual/IP-Comp Curry Paste | D3: Video | E3: B0G1YXWM2P | F3: B079H3DFP7 B0FLP9NYR1 B07BH4B384 B08MFLHMJC B0CY8KKGGP B09BD5VW64 B09BD5BNJ7 B0917NY7X6 B09BD583S6 B08H284SNC B0777JV82Z B0BV76DCY6 B0DPJ3P467 B0C53VBXVM B0BV7783X7 B0C58S9P1K
A5: Consideration | B5: SD/Contextual/Contextual/CT | C5: Chettinad Paste/Contextual/CT-Pastes | D5: Video | E5: B0G1YXWM2P | F5: Cooking & Baking Supplies›Spices & Masalas›Powdered Spices, Seasonings & Masalas›Mixed Spices & Seasonings›Ready Masalas & Curry Powder
A7: Conversion | B7: SD/Contextual/Remarketing/Views | C7: Chettinad Paste/Remarketing/Views | D7: Video | E7: B0G1YXWM2P | F7: Viewed>Advertised>Product, Viewed>Similar Product, Viewed>Category Lookback Period>7Days
A9: Conversion | B9: SD/Contextual/Remarketing/Purchases | C9: Chettinad Paste/Remarketing/Purchase | D9: Video | E9: B0G1YXWM2P | F9: Purchased>Advertised>Product, Purchased>Similar Product, Purchased>Category Lookback Period>30Days
A11: Conversion | B11: SD/Contextual/Inmarketing | C11: Chettinad Paste/Inmarketing | D11: Video | E11: B0G1YXWM2P | F11: In-market: Spices & Masalas In-market: Cooking Pastes & Sauces In-market: Ready to Cook Foods
A13: Conversion | B13: SD/Chettinad Chicken/Contextual/IP | C13: Chettinad Paste/Contextual/IP-Brand Curry Paste | D13: Video | E13: B0G1YXWM2P | F13: B0G1YZ3K4T B0G1Z87RV9 B0CL9D1PHY B0G1YZ5K91

Sheet Media Planning
B3: Media Plan
B4: Duration | C4: Spend | D4: Impressions | E4: CPM | F4: CTR | G4: Clicks | H4: CPC | I4: Sales | J4: Orders | K4: CVR | L4: CPA | M4: AOV | N4: ACOS | O4: Roas
B5: Month 1 | C5: =I5/O5 | D5: =G5/F5 | E5: =C5/D5*1000 | F5: 0.004 | G5: =C5/H5 | H5: 12 | I5: 300000 | J5: =I5/M5 | K5: 0.08 | L5: =C5/J5 | M5: 450 | N5: =C5/I5 | O5: 3
B6: Month 2 | C6: =I6/O6 | D6: =G6/F6 | E6: =C6/D6*1000 | F6: 0.004 | G6: =C6/H6 | H6: 12 | I6: 300000 | J6: =I6/M6 | K6: 0.08 | L6: =C6/J6 | M6: 450 | N6: =C6/I6 | O6: 3
B7: Month 3 | C7: =I7/O7 | D7: =G7/F7 | E7: =C7/D7*1000 | F7: 0.004 | G7: =C7/H7 | H7: 12 | I7: 600000 | J7: =I7/M7 | K7: 0.08 | L7: =C7/J7 | M7: 450 | N7: =C7/I7 | O7: 3
B8: Month 4 | C8: =I8/O8 | D8: =G8/F8 | E8: =C8/D8*1000 | F8: 0.004 | G8: =C8/H8 | H8: 12 | I8: 600000 | J8: =I8/M8 | K8: 0.08 | L8: =C8/J8 | M8: 450 | N8: =C8/I8 | O8: 3
B9: Month 5 | C9: =I9/O9 | D9: =G9/F9 | E9: =C9/D9*1000 | F9: 0.004 | G9: =C9/H9 | H9: 12 | I9: 1000000 | J9: =I9/M9 | K9: 0.08 | L9: =C9/J9 | M9: 450 | N9: =C9/I9 | O9: 3
B10: Month 6 | C10: =I10/O10 | D10: =G10/F10 | E10: =C10/D10*1000 | F10: 0.004 | G10: =C10/H10 | H10: 12 | I10: 1000000 | J10: =I10/M10 | K10: 0.08 | L10: =C10/J10 | M10: 450 | N10: =C10/I10 | O10: 3
B11: Total amount | C11: =SUM(C5:C10)
C13: Assumed | D13: Reason
C14: ACOS | D14: Assumed the ACOS as per benchmark which is highest at the awareness stage and goes down gradually down the funnel.
C15: CTR | D15: Assumed the CTR as per benchmark which is lowest at the awareness stage and goes up gradually down the funnel.
C16: CPC | D16: Assumed the CPC as per benchmark which is highest at the awareness stage and goes down gradually down the funnel.
C17: AOV | D17: Assumed the AOV as ₹450 = CURRYiT combo pack of 3 pastes (given in the CURRYiT deck).

Sheet Month 1 and 2
A1: Month 1 & 2 – Launch and learn
A2: Phase budget (2 months, from Media Planning) | B2: ='Media Planning'!C5+'Media Planning'!C6 | C2: Yellow = input (share / benchmark). Everything else is a formula: Clicks = Spend ÷ CPC, Impressions = Clicks ÷ CTR, Orders = Clicks × CVR, Sales = Orders × AOV ₹450.
A4: A. Split by ad type
A5: Ad type | B5: Spend | C5: Impressions | D5: CPM | E5: CTR | F5: Clicks | G5: CPC | H5: Orders | I5: CVR | J5: CPA | K5: AOV | L5: Sales | M5: ACOS | N5: ROAS | O5: Share
A6: Sponsored Products | B6: =$B$2*O6 | C6: =F6/E6 | D6: =B6/C6*1000 | E6: 0.004 | F6: =B6/G6 | G6: 12 | H6: =F6*I6 | I6: 0.08 | J6: =B6/H6 | K6: =AOV | L6: =H6*K6 | M6: =B6/L6 | N6: =L6/B6 | O6: 0.6
A7: Sponsored Brands | B7: =$B$2*O7 | C7: =F7/E7 | D7: =B7/C7*1000 | E7: 0.005 | F7: =B7/G7 | G7: 15 | H7: =F7*I7 | I7: 0.1 | J7: =B7/H7 | K7: =AOV | L7: =H7*K7 | M7: =B7/L7 | N7: =L7/B7 | O7: 0.25
A8: Sponsored Display | B8: =$B$2*O8 | C8: =F8/E8 | D8: =B8/C8*1000 | E8: 0.0025 | F8: =B8/G8 | G8: 9 | H8: =F8*I8 | I8: 0.06 | J8: =B8/H8 | K8: =AOV | L8: =H8*K8 | M8: =B8/L8 | N8: =L8/B8 | O8: 0.15
A9: Total | B9: =SUM(B6:B8) | C9: =SUM(C6:C8) | D9: =B9/C9*1000 | E9: =F9/C9 | F9: =SUM(F6:F8) | G9: =B9/F9 | H9: =SUM(H6:H8) | I9: =H9/F9 | J9: =B9/H9 | K9: =L9/H9 | L9: =SUM(L6:L8) | M9: =B9/L9 | N9: =L9/B9 | O9: =SUM(O6:O8)
A11: B. SP campaigns
A12: Campaign | B12: Spend | C12: Impressions | D12: CPM | E12: CTR | F12: Clicks | G12: CPC | H12: Orders | I12: CVR | J12: CPA | K12: AOV | L12: Sales | M12: ACOS | N12: ROAS | O12: Share in SP | P12: Why
A13: SP/ChettinadChicken/Auto | B13: =$B$6*O13 | C13: =F13/E13 | D13: =B13/C13*1000 | E13: =$E$6 | F13: =B13/G13 | G13: =$G$6 | H13: =F13*I13 | I13: =$I$6 | J13: =B13/H13 | K13: =AOV | L13: =H13*K13 | M13: =B13/L13 | N13: =L13/B13 | O13: 0.2 | P13: Find new keywords; check search terms weekly
A14: SP/ChettinadChicken/Brand KWs/Exact | B14: =$B$6*O14 | C14: =F14/E14 | D14: =B14/C14*1000 | E14: =$E$6 | F14: =B14/G14 | G14: =$G$6 | H14: =F14*I14 | I14: =$I$6 | J14: =B14/H14 | K14: =AOV | L14: =H14*K14 | M14: =B14/L14 | N14: =L14/B14 | O14: 0.06 | P14: Protect "curry it / curryit" (3,700 searches)
A15: SP/ChettinadChicken/Brand KWs/Phrase | B15: =$B$6*O15 | C15: =F15/E15 | D15: =B15/C15*1000 | E15: =$E$6 | F15: =B15/G15 | G15: =$G$6 | H15: =F15*I15 | I15: =$I$6 | J15: =B15/H15 | K15: =AOV | L15: =H15*K15 | M15: =B15/L15 | N15: =L15/B15 | O15: 0.04
A16: SP/ChettinadChicken/Brand KWs/Broad | B16: =$B$6*O16 | C16: =F16/E16 | D16: =B16/C16*1000 | E16: =$E$6 | F16: =B16/G16 | G16: =$G$6 | H16: =F16*I16 | I16: =$I$6 | J16: =B16/H16 | K16: =AOV | L16: =H16*K16 | M16: =B16/L16 | N16: =L16/B16 | O16: 0.02
A17: SP/ChettinadChicken/Generic KWs/Exact | B17: =$B$6*O17 | C17: =F17/E17 | D17: =B17/C17*1000 | E17: =$E$6 | F17: =B17/G17 | G17: =$G$6 | H17: =F17*I17 | I17: =$I$6 | J17: =B17/H17 | K17: =AOV | L17: =H17*K17 | M17: =B17/L17 | N17: =L17/B17 | O17: 0.18 | P17: Main pool: 4,190 generic searches (Priority 1)
A18: SP/ChettinadChicken/Generic KWs/Phrase | B18: =$B$6*O18 | C18: =F18/E18 | D18: =B18/C18*1000 | E18: =$E$6 | F18: =B18/G18 | G18: =$G$6 | H18: =F18*I18 | I18: =$I$6 | J18: =B18/H18 | K18: =AOV | L18: =H18*K18 | M18: =B18/L18 | N18: =L18/B18 | O18: 0.12
A19: SP/ChettinadChicken/Generic KWs/Broad | B19: =$B$6*O19 | C19: =F19/E19 | D19: =B19/C19*1000 | E19: =$E$6 | F19: =B19/G19 | G19: =$G$6 | H19: =F19*I19 | I19: =$I$6 | J19: =B19/H19 | K19: =AOV | L19: =H19*K19 | M19: =B19/L19 | N19: =L19/B19 | O19: 0.06
A20: SP/ChettinadChicken/Comp KWs/Exact | B20: =$B$6*O20 | C20: =F20/E20 | D20: =B20/C20*1000 | E20: =$E$6 | F20: =B20/G20 | G20: =$G$6 | H20: =F20*I20 | I20: =$I$6 | J20: =B20/H20 | K20: =AOV | L20: =H20*K20 | M20: =B20/L20 | N20: =L20/B20 | O20: 0.08 | P20: Comp pool only 820 searches
A21: SP/ChettinadChicken/Comp KWs/Phrase | B21: =$B$6*O21 | C21: =F21/E21 | D21: =B21/C21*1000 | E21: =$E$6 | F21: =B21/G21 | G21: =$G$6 | H21: =F21*I21 | I21: =$I$6 | J21: =B21/H21 | K21: =AOV | L21: =H21*K21 | M21: =B21/L21 | N21: =L21/B21 | O21: 0.05
A22: SP/ChettinadChicken/Comp KWs/Broad | B22: =$B$6*O22 | C22: =F22/E22 | D22: =B22/C22*1000 | E22: =$E$6 | F22: =B22/G22 | G22: =$G$6 | H22: =F22*I22 | I22: =$I$6 | J22: =B22/H22 | K22: =AOV | L22: =H22*K22 | M22: =B22/L22 | N22: =L22/B22 | O22: 0.03
A23: SP/ChettinadChicken/CT | B23: =$B$6*O23 | C23: =F23/E23 | D23: =B23/C23*1000 | E23: =$E$6 | F23: =B23/G23 | G23: =$G$6 | H23: =F23*I23 | I23: =$I$6 | J23: =B23/H23 | K23: =AOV | L23: =H23*K23 | M23: =B23/L23 | N23: =L23/B23 | O23: 0.06 | P23: Category reach
A24: SP/ChettinadChicken/IP/CompTar | B24: =$B$6*O24 | C24: =F24/E24 | D24: =B24/C24*1000 | E24: =$E$6 | F24: =B24/G24 | G24: =$G$6 | H24: =F24*I24 | I24: =$I$6 | J24: =B24/H24 | K24: =AOV | L24: =H24*K24 | M24: =B24/L24 | N24: =L24/B24 | O24: 0.07 | P24: Competitor product pages
A25: SP/ChettinadChicken/IP/BrandTar | B25: =$B$6*O25 | C25: =F25/E25 | D25: =B25/C25*1000 | E25: =$E$6 | F25: =B25/G25 | G25: =$G$6 | H25: =F25*I25 | I25: =$I$6 | J25: =B25/H25 | K25: =AOV | L25: =H25*K25 | M25: =B25/L25 | N25: =L25/B25 | O25: 0.03 | P25: Defend own pages
A26: Total SP | B26: =SUM(B13:B25) | C26: =SUM(C13:C25) | D26: =B26/C26*1000 | E26: =F26/C26 | F26: =SUM(F13:F25) | G26: =B26/F26 | H26: =SUM(H13:H25) | I26: =H26/F26 | J26: =B26/H26 | K26: =L26/H26 | L26: =SUM(L13:L25) | M26: =B26/L26 | N26: =L26/B26 | O26: =SUM(O13:O25)
A28: B. SB campaigns
A29: Campaign | B29: Spend | C29: Impressions | D29: CPM | E29: CTR | F29: Clicks | G29: CPC | H29: Orders | I29: CVR | J29: CPA | K29: AOV | L29: Sales | M29: ACOS | N29: ROAS | O29: Share in SB | P29: Why
A30: SB/Video/Brand kws-Exact | B30: =$B$7*O30 | C30: =F30/E30 | D30: =B30/C30*1000 | E30: =$E$7 | F30: =B30/G30 | G30: =$G$7 | H30: =F30*I30 | I30: =$I$7 | J30: =B30/H30 | K30: =AOV | L30: =H30*K30 | M30: =B30/L30 | N30: =L30/B30 | O30: 0.15 | P30: Brand video
A31: SB/Video/Brand kws-Phrase | B31: =$B$7*O31 | C31: =F31/E31 | D31: =B31/C31*1000 | E31: =$E$7 | F31: =B31/G31 | G31: =$G$7 | H31: =F31*I31 | I31: =$I$7 | J31: =B31/H31 | K31: =AOV | L31: =H31*K31 | M31: =B31/L31 | N31: =L31/B31 | O31: 0.1
A32: SB/Video/Generic Chettinad kws-Exact | B32: =$B$7*O32 | C32: =F32/E32 | D32: =B32/C32*1000 | E32: =$E$7 | F32: =B32/G32 | G32: =$G$7 | H32: =F32*I32 | I32: =$I$7 | J32: =B32/H32 | K32: =AOV | L32: =H32*K32 | M32: =B32/L32 | N32: =L32/B32 | O32: 0.3 | P32: 15-min video on generic search
A33: SB/Video/Generic Chettinad kws-Phrase | B33: =$B$7*O33 | C33: =F33/E33 | D33: =B33/C33*1000 | E33: =$E$7 | F33: =B33/G33 | G33: =$G$7 | H33: =F33*I33 | I33: =$I$7 | J33: =B33/H33 | K33: =AOV | L33: =H33*K33 | M33: =B33/L33 | N33: =L33/B33 | O33: 0.2
A34: SB/Video/Comp kws-Exact | B34: =$B$7*O34 | C34: =F34/E34 | D34: =B34/C34*1000 | E34: =$E$7 | F34: =B34/G34 | G34: =$G$7 | H34: =F34*I34 | I34: =$I$7 | J34: =B34/H34 | K34: =AOV | L34: =H34*K34 | M34: =B34/L34 | N34: =L34/B34 | O34: 0.15 | P34: Video to make comp shopper switch
A35: SB/Video/Comp kws-Phrase | B35: =$B$7*O35 | C35: =F35/E35 | D35: =B35/C35*1000 | E35: =$E$7 | F35: =B35/G35 | G35: =$G$7 | H35: =F35*I35 | I35: =$I$7 | J35: =B35/H35 | K35: =AOV | L35: =H35*K35 | M35: =B35/L35 | N35: =L35/B35 | O35: 0.1
A36: Total SB | B36: =SUM(B30:B35) | C36: =SUM(C30:C35) | D36: =B36/C36*1000 | E36: =F36/C36 | F36: =SUM(F30:F35) | G36: =B36/F36 | H36: =SUM(H30:H35) | I36: =H36/F36 | J36: =B36/H36 | K36: =L36/H36 | L36: =SUM(L30:L35) | M36: =B36/L36 | N36: =L36/B36 | O36: =SUM(O30:O35)
A38: B. SD campaigns
A39: Campaign | B39: Spend | C39: Impressions | D39: CPM | E39: CTR | F39: Clicks | G39: CPC | H39: Orders | I39: CVR | J39: CPA | K39: AOV | L39: Sales | M39: ACOS | N39: ROAS | O39: Share in SD | P39: Why
A40: SD/Remarketing/Views | B40: =$B$8*O40 | C40: =F40/E40 | D40: =B40/C40*1000 | E40: =$E$8 | F40: =B40/G40 | G40: =$G$8 | H40: =F40*I40 | I40: =$I$8 | J40: =B40/H40 | K40: =AOV | L40: =H40*K40 | M40: =B40/L40 | N40: =L40/B40 | O40: 0.5 | P40: Viewed but did not buy
A41: SD/Contextual/IP-Comp | B41: =$B$8*O41 | C41: =F41/E41 | D41: =B41/C41*1000 | E41: =$E$8 | F41: =B41/G41 | G41: =$G$8 | H41: =F41*I41 | I41: =$I$8 | J41: =B41/H41 | K41: =AOV | L41: =H41*K41 | M41: =B41/L41 | N41: =L41/B41 | O41: 0.25 | P41: Competitor pages
A42: SD/Contextual/CT | B42: =$B$8*O42 | C42: =F42/E42 | D42: =B42/C42*1000 | E42: =$E$8 | F42: =B42/G42 | G42: =$G$8 | H42: =F42*I42 | I42: =$I$8 | J42: =B42/H42 | K42: =AOV | L42: =H42*K42 | M42: =B42/L42 | N42: =L42/B42 | O42: 0.15 | P42: Category pages
A43: SD/Contextual/IP-Brand | B43: =$B$8*O43 | C43: =F43/E43 | D43: =B43/C43*1000 | E43: =$E$8 | F43: =B43/G43 | G43: =$G$8 | H43: =F43*I43 | I43: =$I$8 | J43: =B43/H43 | K43: =AOV | L43: =H43*K43 | M43: =B43/L43 | N43: =L43/B43 | O43: 0.1 | P43: Own pages
A44: Total SD | B44: =SUM(B40:B43) | C44: =SUM(C40:C43) | D44: =B44/C44*1000 | E44: =F44/C44 | F44: =SUM(F40:F43) | G44: =B44/F44 | H44: =SUM(H40:H43) | I44: =H44/F44 | J44: =B44/H44 | K44: =L44/H44 | L44: =SUM(L40:L43) | M44: =B44/L44 | N44: =L44/B44 | O44: =SUM(O40:O43)

Sheet Month 3 and 4
A1: Month 3 & 4 – Grow what works
A2: Phase budget (2 months, from Media Planning) | B2: ='Media Planning'!C7+'Media Planning'!C8 | C2: Yellow = input (share / benchmark). Everything else is a formula: Clicks = Spend ÷ CPC, Impressions = Clicks ÷ CTR, Orders = Clicks × CVR, Sales = Orders × AOV ₹450.
A4: A. Split by ad type
A5: Ad type | B5: Spend | C5: Impressions | D5: CPM | E5: CTR | F5: Clicks | G5: CPC | H5: Orders | I5: CVR | J5: CPA | K5: AOV | L5: Sales | M5: ACOS | N5: ROAS | O5: Share
A6: Sponsored Products | B6: =$B$2*O6 | C6: =F6/E6 | D6: =B6/C6*1000 | E6: 0.004 | F6: =B6/G6 | G6: 12 | H6: =F6*I6 | I6: 0.08 | J6: =B6/H6 | K6: =AOV | L6: =H6*K6 | M6: =B6/L6 | N6: =L6/B6 | O6: 0.55
A7: Sponsored Brands | B7: =$B$2*O7 | C7: =F7/E7 | D7: =B7/C7*1000 | E7: 0.005 | F7: =B7/G7 | G7: 15 | H7: =F7*I7 | I7: 0.1 | J7: =B7/H7 | K7: =AOV | L7: =H7*K7 | M7: =B7/L7 | N7: =L7/B7 | O7: 0.27
A8: Sponsored Display | B8: =$B$2*O8 | C8: =F8/E8 | D8: =B8/C8*1000 | E8: 0.0025 | F8: =B8/G8 | G8: 9 | H8: =F8*I8 | I8: 0.06 | J8: =B8/H8 | K8: =AOV | L8: =H8*K8 | M8: =B8/L8 | N8: =L8/B8 | O8: 0.18
A9: Total | B9: =SUM(B6:B8) | C9: =SUM(C6:C8) | D9: =B9/C9*1000 | E9: =F9/C9 | F9: =SUM(F6:F8) | G9: =B9/F9 | H9: =SUM(H6:H8) | I9: =H9/F9 | J9: =B9/H9 | K9: =L9/H9 | L9: =SUM(L6:L8) | M9: =B9/L9 | N9: =L9/B9 | O9: =SUM(O6:O8)
A11: B. SP campaigns
A12: Campaign | B12: Spend | C12: Impressions | D12: CPM | E12: CTR | F12: Clicks | G12: CPC | H12: Orders | I12: CVR | J12: CPA | K12: AOV | L12: Sales | M12: ACOS | N12: ROAS | O12: Share in SP | P12: Why
A13: SP/ChettinadChicken/Auto | B13: =$B$6*O13 | C13: =F13/E13 | D13: =B13/C13*1000 | E13: =$E$6 | F13: =B13/G13 | G13: =$G$6 | H13: =F13*I13 | I13: =$I$6 | J13: =B13/H13 | K13: =AOV | L13: =H13*K13 | M13: =B13/L13 | N13: =L13/B13 | O13: 0.12 | P13: Cut: winners moved to Exact
A14: SP/ChettinadChicken/Brand KWs/Exact | B14: =$B$6*O14 | C14: =F14/E14 | D14: =B14/C14*1000 | E14: =$E$6 | F14: =B14/G14 | G14: =$G$6 | H14: =F14*I14 | I14: =$I$6 | J14: =B14/H14 | K14: =AOV | L14: =H14*K14 | M14: =B14/L14 | N14: =L14/B14 | O14: 0.06
A15: SP/ChettinadChicken/Brand KWs/Phrase | B15: =$B$6*O15 | C15: =F15/E15 | D15: =B15/C15*1000 | E15: =$E$6 | F15: =B15/G15 | G15: =$G$6 | H15: =F15*I15 | I15: =$I$6 | J15: =B15/H15 | K15: =AOV | L15: =H15*K15 | M15: =B15/L15 | N15: =L15/B15 | O15: 0.04
A16: SP/ChettinadChicken/Brand KWs/Broad | B16: =$B$6*O16 | C16: =F16/E16 | D16: =B16/C16*1000 | E16: =$E$6 | F16: =B16/G16 | G16: =$G$6 | H16: =F16*I16 | I16: =$I$6 | J16: =B16/H16 | K16: =AOV | L16: =H16*K16 | M16: =B16/L16 | N16: =L16/B16 | O16: 0.02
A17: SP/ChettinadChicken/Generic KWs/Exact | B17: =$B$6*O17 | C17: =F17/E17 | D17: =B17/C17*1000 | E17: =$E$6 | F17: =B17/G17 | G17: =$G$6 | H17: =F17*I17 | I17: =$I$6 | J17: =B17/H17 | K17: =AOV | L17: =H17*K17 | M17: =B17/L17 | N17: =L17/B17 | O17: 0.22 | P17: Scale proven keywords
A18: SP/ChettinadChicken/Generic KWs/Phrase | B18: =$B$6*O18 | C18: =F18/E18 | D18: =B18/C18*1000 | E18: =$E$6 | F18: =B18/G18 | G18: =$G$6 | H18: =F18*I18 | I18: =$I$6 | J18: =B18/H18 | K18: =AOV | L18: =H18*K18 | M18: =B18/L18 | N18: =L18/B18 | O18: 0.14
A19: SP/ChettinadChicken/Generic KWs/Broad | B19: =$B$6*O19 | C19: =F19/E19 | D19: =B19/C19*1000 | E19: =$E$6 | F19: =B19/G19 | G19: =$G$6 | H19: =F19*I19 | I19: =$I$6 | J19: =B19/H19 | K19: =AOV | L19: =H19*K19 | M19: =B19/L19 | N19: =L19/B19 | O19: 0.06
A20: SP/ChettinadChicken/Comp KWs/Exact | B20: =$B$6*O20 | C20: =F20/E20 | D20: =B20/C20*1000 | E20: =$E$6 | F20: =B20/G20 | G20: =$G$6 | H20: =F20*I20 | I20: =$I$6 | J20: =B20/H20 | K20: =AOV | L20: =H20*K20 | M20: =B20/L20 | N20: =L20/B20 | O20: 0.09
A21: SP/ChettinadChicken/Comp KWs/Phrase | B21: =$B$6*O21 | C21: =F21/E21 | D21: =B21/C21*1000 | E21: =$E$6 | F21: =B21/G21 | G21: =$G$6 | H21: =F21*I21 | I21: =$I$6 | J21: =B21/H21 | K21: =AOV | L21: =H21*K21 | M21: =B21/L21 | N21: =L21/B21 | O21: 0.06
A22: SP/ChettinadChicken/Comp KWs/Broad | B22: =$B$6*O22 | C22: =F22/E22 | D22: =B22/C22*1000 | E22: =$E$6 | F22: =B22/G22 | G22: =$G$6 | H22: =F22*I22 | I22: =$I$6 | J22: =B22/H22 | K22: =AOV | L22: =H22*K22 | M22: =B22/L22 | N22: =L22/B22 | O22: 0.03
A23: SP/ChettinadChicken/CT | B23: =$B$6*O23 | C23: =F23/E23 | D23: =B23/C23*1000 | E23: =$E$6 | F23: =B23/G23 | G23: =$G$6 | H23: =F23*I23 | I23: =$I$6 | J23: =B23/H23 | K23: =AOV | L23: =H23*K23 | M23: =B23/L23 | N23: =L23/B23 | O23: 0.05
A24: SP/ChettinadChicken/IP/CompTar | B24: =$B$6*O24 | C24: =F24/E24 | D24: =B24/C24*1000 | E24: =$E$6 | F24: =B24/G24 | G24: =$G$6 | H24: =F24*I24 | I24: =$I$6 | J24: =B24/H24 | K24: =AOV | L24: =H24*K24 | M24: =B24/L24 | N24: =L24/B24 | O24: 0.08 | P24: More on comp pages that converted
A25: SP/ChettinadChicken/IP/BrandTar | B25: =$B$6*O25 | C25: =F25/E25 | D25: =B25/C25*1000 | E25: =$E$6 | F25: =B25/G25 | G25: =$G$6 | H25: =F25*I25 | I25: =$I$6 | J25: =B25/H25 | K25: =AOV | L25: =H25*K25 | M25: =B25/L25 | N25: =L25/B25 | O25: 0.03
A26: Total SP | B26: =SUM(B13:B25) | C26: =SUM(C13:C25) | D26: =B26/C26*1000 | E26: =F26/C26 | F26: =SUM(F13:F25) | G26: =B26/F26 | H26: =SUM(H13:H25) | I26: =H26/F26 | J26: =B26/H26 | K26: =L26/H26 | L26: =SUM(L13:L25) | M26: =B26/L26 | N26: =L26/B26 | O26: =SUM(O13:O25)
A28: B. SB campaigns
A29: Campaign | B29: Spend | C29: Impressions | D29: CPM | E29: CTR | F29: Clicks | G29: CPC | H29: Orders | I29: CVR | J29: CPA | K29: AOV | L29: Sales | M29: ACOS | N29: ROAS | O29: Share in SB | P29: Why
A30: SB Brand – Product Collection (Combo-3) | B30: =$B$7*O30 | C30: =F30/E30 | D30: =B30/C30*1000 | E30: =$E$7 | F30: =B30/G30 | G30: =$G$7 | H30: =F30*I30 | I30: =$I$7 | J30: =B30/H30 | K30: =AOV | L30: =H30*K30 | M30: =B30/L30 | N30: =L30/B30 | O30: 0.2 | P30: NEW: deck says SB Brand starts M3, sells combo
A31: SB/Video/Brand kws-Exact | B31: =$B$7*O31 | C31: =F31/E31 | D31: =B31/C31*1000 | E31: =$E$7 | F31: =B31/G31 | G31: =$G$7 | H31: =F31*I31 | I31: =$I$7 | J31: =B31/H31 | K31: =AOV | L31: =H31*K31 | M31: =B31/L31 | N31: =L31/B31 | O31: 0.12
A32: SB/Video/Brand kws-Phrase | B32: =$B$7*O32 | C32: =F32/E32 | D32: =B32/C32*1000 | E32: =$E$7 | F32: =B32/G32 | G32: =$G$7 | H32: =F32*I32 | I32: =$I$7 | J32: =B32/H32 | K32: =AOV | L32: =H32*K32 | M32: =B32/L32 | N32: =L32/B32 | O32: 0.08
A33: SB/Video/Generic Chettinad kws-Exact | B33: =$B$7*O33 | C33: =F33/E33 | D33: =B33/C33*1000 | E33: =$E$7 | F33: =B33/G33 | G33: =$G$7 | H33: =F33*I33 | I33: =$I$7 | J33: =B33/H33 | K33: =AOV | L33: =H33*K33 | M33: =B33/L33 | N33: =L33/B33 | O33: 0.25
A34: SB/Video/Generic Chettinad kws-Phrase | B34: =$B$7*O34 | C34: =F34/E34 | D34: =B34/C34*1000 | E34: =$E$7 | F34: =B34/G34 | G34: =$G$7 | H34: =F34*I34 | I34: =$I$7 | J34: =B34/H34 | K34: =AOV | L34: =H34*K34 | M34: =B34/L34 | N34: =L34/B34 | O34: 0.15
A35: SB/Video/Comp kws-Exact | B35: =$B$7*O35 | C35: =F35/E35 | D35: =B35/C35*1000 | E35: =$E$7 | F35: =B35/G35 | G35: =$G$7 | H35: =F35*I35 | I35: =$I$7 | J35: =B35/H35 | K35: =AOV | L35: =H35*K35 | M35: =B35/L35 | N35: =L35/B35 | O35: 0.12
A36: SB/Video/Comp kws-Phrase | B36: =$B$7*O36 | C36: =F36/E36 | D36: =B36/C36*1000 | E36: =$E$7 | F36: =B36/G36 | G36: =$G$7 | H36: =F36*I36 | I36: =$I$7 | J36: =B36/H36 | K36: =AOV | L36: =H36*K36 | M36: =B36/L36 | N36: =L36/B36 | O36: 0.08
A37: Total SB | B37: =SUM(B30:B36) | C37: =SUM(C30:C36) | D37: =B37/C37*1000 | E37: =F37/C37 | F37: =SUM(F30:F36) | G37: =B37/F37 | H37: =SUM(H30:H36) | I37: =H37/F37 | J37: =B37/H37 | K37: =L37/H37 | L37: =SUM(L30:L36) | M37: =B37/L37 | N37: =L37/B37 | O37: =SUM(O30:O36)
A39: B. SD campaigns
A40: Campaign | B40: Spend | C40: Impressions | D40: CPM | E40: CTR | F40: Clicks | G40: CPC | H40: Orders | I40: CVR | J40: CPA | K40: AOV | L40: Sales | M40: ACOS | N40: ROAS | O40: Share in SD | P40: Why
A41: SD/Remarketing/Views | B41: =$B$8*O41 | C41: =F41/E41 | D41: =B41/C41*1000 | E41: =$E$8 | F41: =B41/G41 | G41: =$G$8 | H41: =F41*I41 | I41: =$I$8 | J41: =B41/H41 | K41: =AOV | L41: =H41*K41 | M41: =B41/L41 | N41: =L41/B41 | O41: 0.4 | P41: Bigger viewer pool now
A42: SD/Remarketing/Purchases | B42: =$B$8*O42 | C42: =F42/E42 | D42: =B42/C42*1000 | E42: =$E$8 | F42: =B42/G42 | G42: =$G$8 | H42: =F42*I42 | I42: =$I$8 | J42: =B42/H42 | K42: =AOV | L42: =H42*K42 | M42: =B42/L42 | N42: =L42/B42 | O42: 0.1 | P42: NEW: first buyers to rebuy
A43: SD/Contextual/IP-Comp | B43: =$B$8*O43 | C43: =F43/E43 | D43: =B43/C43*1000 | E43: =$E$8 | F43: =B43/G43 | G43: =$G$8 | H43: =F43*I43 | I43: =$I$8 | J43: =B43/H43 | K43: =AOV | L43: =H43*K43 | M43: =B43/L43 | N43: =L43/B43 | O43: 0.2
A44: SD/Contextual/CT | B44: =$B$8*O44 | C44: =F44/E44 | D44: =B44/C44*1000 | E44: =$E$8 | F44: =B44/G44 | G44: =$G$8 | H44: =F44*I44 | I44: =$I$8 | J44: =B44/H44 | K44: =AOV | L44: =H44*K44 | M44: =B44/L44 | N44: =L44/B44 | O44: 0.1
...

Sheet Month 5 and 6
A1: Month 5 & 6 – Hit ₹10L a month
A2: Phase budget (2 months, from Media Planning) | B2: ='Media Planning'!C9+'Media Planning'!C10 | C2: Yellow = input (share / benchmark). Everything else is a formula: Clicks = Spend ÷ CPC, Impressions = Clicks ÷ CTR, Orders = Clicks × CVR, Sales = Orders × AOV ₹450.
A4: A. Split by ad type
A5: Ad type | B5: Spend | C5: Impressions | D5: CPM | E5: CTR | F5: Clicks | G5: CPC | H5: Orders | I5: CVR | J5: CPA | K5: AOV | L5: Sales | M5: ACOS | N5: ROAS | O5: Share
A6: Sponsored Products | B6: =$B$2*O6 | C6: =F6/E6 | D6: =B6/C6*1000 | E6: 0.004 | F6: =B6/G6 | G6: 12 | H6: =F6*I6 | I6: 0.08 | J6: =B6/H6 | K6: =AOV | L6: =H6*K6 | M6: =B6/L6 | N6: =L6/B6 | O6: 0.5
A7: Sponsored Brands | B7: =$B$2*O7 | C7: =F7/E7 | D7: =B7/C7*1000 | E7: 0.005 | F7: =B7/G7 | G7: 15 | H7: =F7*I7 | I7: 0.1 | J7: =B7/H7 | K7: =AOV | L7: =H7*K7 | M7: =B7/L7 | N7: =L7/B7 | O7: 0.28
A8: Sponsored Display | B8: =$B$2*O8 | C8: =F8/E8 | D8: =B8/C8*1000 | E8: 0.0025 | F8: =B8/G8 | G8: 9 | H8: =F8*I8 | I8: 0.06 | J8: =B8/H8 | K8: =AOV | L8: =H8*K8 | M8: =B8/L8 | N8: =L8/B8 | O8: 0.22
A9: Total | B9: =SUM(B6:B8) | C9: =SUM(C6:C8) | D9: =B9/C9*1000 | E9: =F9/C9 | F9: =SUM(F6:F8) | G9: =B9/F9 | H9: =SUM(H6:H8) | I9: =H9/F9 | J9: =B9/H9 | K9: =L9/H9 | L9: =SUM(L6:L8) | M9: =B9/L9 | N9: =L9/B9 | O9: =SUM(O6:O8)
A11: B. SP campaigns
A12: Campaign | B12: Spend | C12: Impressions | D12: CPM | E12: CTR | F12: Clicks | G12: CPC | H12: Orders | I12: CVR | J12: CPA | K12: AOV | L12: Sales | M12: ACOS | N12: ROAS | O12: Share in SP | P12: Why
A13: SP/ChettinadChicken/Auto | B13: =$B$6*O13 | C13: =F13/E13 | D13: =B13/C13*1000 | E13: =$E$6 | F13: =B13/G13 | G13: =$G$6 | H13: =F13*I13 | I13: =$I$6 | J13: =B13/H13 | K13: =AOV | L13: =H13*K13 | M13: =B13/L13 | N13: =L13/B13 | O13: 0.08 | P13: Tighten, do not expand
A14: SP/ChettinadChicken/Brand KWs/Exact | B14: =$B$6*O14 | C14: =F14/E14 | D14: =B14/C14*1000 | E14: =$E$6 | F14: =B14/G14 | G14: =$G$6 | H14: =F14*I14 | I14: =$I$6 | J14: =B14/H14 | K14: =AOV | L14: =H14*K14 | M14: =B14/L14 | N14: =L14/B14 | O14: 0.07 | P14: Protect brand at top of search
A15: SP/ChettinadChicken/Brand KWs/Phrase | B15: =$B$6*O15 | C15: =F15/E15 | D15: =B15/C15*1000 | E15: =$E$6 | F15: =B15/G15 | G15: =$G$6 | H15: =F15*I15 | I15: =$I$6 | J15: =B15/H15 | K15: =AOV | L15: =H15*K15 | M15: =B15/L15 | N15: =L15/B15 | O15: 0.04
A16: SP/ChettinadChicken/Brand KWs/Broad | B16: =$B$6*O16 | C16: =F16/E16 | D16: =B16/C16*1000 | E16: =$E$6 | F16: =B16/G16 | G16: =$G$6 | H16: =F16*I16 | I16: =$I$6 | J16: =B16/H16 | K16: =AOV | L16: =H16*K16 | M16: =B16/L16 | N16: =L16/B16 | O16: 0.02
A17: SP/ChettinadChicken/Generic KWs/Exact | B17: =$B$6*O17 | C17: =F17/E17 | D17: =B17/C17*1000 | E17: =$E$6 | F17: =B17/G17 | G17: =$G$6 | H17: =F17*I17 | I17: =$I$6 | J17: =B17/H17 | K17: =AOV | L17: =H17*K17 | M17: =B17/L17 | N17: =L17/B17 | O17: 0.25 | P17: Most budget on proven Exact
A18: SP/ChettinadChicken/Generic KWs/Phrase | B18: =$B$6*O18 | C18: =F18/E18 | D18: =B18/C18*1000 | E18: =$E$6 | F18: =B18/G18 | G18: =$G$6 | H18: =F18*I18 | I18: =$I$6 | J18: =B18/H18 | K18: =AOV | L18: =H18*K18 | M18: =B18/L18 | N18: =L18/B18 | O18: 0.14
A19: SP/ChettinadChicken/Generic KWs/Broad | B19: =$B$6*O19 | C19: =F19/E19 | D19: =B19/C19*1000 | E19: =$E$6 | F19: =B19/G19 | G19: =$G$6 | H19: =F19*I19 | I19: =$I$6 | J19: =B19/H19 | K19: =AOV | L19: =H19*K19 | M19: =B19/L19 | N19: =L19/B19 | O19: 0.05
A20: SP/ChettinadChicken/Comp KWs/Exact | B20: =$B$6*O20 | C20: =F20/E20 | D20: =B20/C20*1000 | E20: =$E$6 | F20: =B20/G20 | G20: =$G$6 | H20: =F20*I20 | I20: =$I$6 | J20: =B20/H20 | K20: =AOV | L20: =H20*K20 | M20: =B20/L20 | N20: =L20/B20 | O20: 0.09
A21: SP/ChettinadChicken/Comp KWs/Phrase | B21: =$B$6*O21 | C21: =F21/E21 | D21: =B21/C21*1000 | E21: =$E$6 | F21: =B21/G21 | G21: =$G$6 | H21: =F21*I21 | I21: =$I$6 | J21: =B21/H21 | K21: =AOV | L21: =H21*K21 | M21: =B21/L21 | N21: =L21/B21 | O21: 0.05
A22: SP/ChettinadChicken/Comp KWs/Broad | B22: =$B$6*O22 | C22: =F22/E22 | D22: =B22/C22*1000 | E22: =$E$6 | F22: =B22/G22 | G22: =$G$6 | H22: =F22*I22 | I22: =$I$6 | J22: =B22/H22 | K22: =AOV | L22: =H22*K22 | M22: =B22/L22 | N22: =L22/B22 | O22: 0.02
A23: SP/ChettinadChicken/CT | B23: =$B$6*O23 | C23: =F23/E23 | D23: =B23/C23*1000 | E23: =$E$6 | F23: =B23/G23 | G23: =$G$6 | H23: =F23*I23 | I23: =$I$6 | J23: =B23/H23 | K23: =AOV | L23: =H23*K23 | M23: =B23/L23 | N23: =L23/B23 | O23: 0.05
A24: SP/ChettinadChicken/IP/CompTar | B24: =$B$6*O24 | C24: =F24/E24 | D24: =B24/C24*1000 | E24: =$E$6 | F24: =B24/G24 | G24: =$G$6 | H24: =F24*I24 | I24: =$I$6 | J24: =B24/H24 | K24: =AOV | L24: =H24*K24 | M24: =B24/L24 | N24: =L24/B24 | O24: 0.1
A25: SP/ChettinadChicken/IP/BrandTar | B25: =$B$6*O25 | C25: =F25/E25 | D25: =B25/C25*1000 | E25: =$E$6 | F25: =B25/G25 | G25: =$G$6 | H25: =F25*I25 | I25: =$I$6 | J25: =B25/H25 | K25: =AOV | L25: =H25*K25 | M25: =B25/L25 | N25: =L25/B25 | O25: 0.04
A26: Total SP | B26: =SUM(B13:B25) | C26: =SUM(C13:C25) | D26: =B26/C26*1000 | E26: =F26/C26 | F26: =SUM(F13:F25) | G26: =B26/F26 | H26: =SUM(H13:H25) | I26: =H26/F26 | J26: =B26/H26 | K26: =L26/H26 | L26: =SUM(L13:L25) | M26: =B26/L26 | N26: =L26/B26 | O26: =SUM(O13:O25)
A28: B. SB campaigns
A29: Campaign | B29: Spend | C29: Impressions | D29: CPM | E29: CTR | F29: Clicks | G29: CPC | H29: Orders | I29: CVR | J29: CPA | K29: AOV | L29: Sales | M29: ACOS | N29: ROAS | O29: Share in SB | P29: Why
A30: SB Brand – Product Collection (Combo-3) | B30: =$B$7*O30 | C30: =F30/E30 | D30: =B30/C30*1000 | E30: =$E$7 | F30: =B30/G30 | G30: =$G$7 | H30: =F30*I30 | I30: =$I$7 | J30: =B30/H30 | K30: =AOV | L30: =H30*K30 | M30: =B30/L30 | N30: =L30/B30 | O30: 0.3 | P30: Combo lifts AOV to ₹450
A31: SB/Video/Brand kws-Exact | B31: =$B$7*O31 | C31: =F31/E31 | D31: =B31/C31*1000 | E31: =$E$7 | F31: =B31/G31 | G31: =$G$7 | H31: =F31*I31 | I31: =$I$7 | J31: =B31/H31 | K31: =AOV | L31: =H31*K31 | M31: =B31/L31 | N31: =L31/B31 | O31: 0.12
A32: SB/Video/Brand kws-Phrase | B32: =$B$7*O32 | C32: =F32/E32 | D32: =B32/C32*1000 | E32: =$E$7 | F32: =B32/G32 | G32: =$G$7 | H32: =F32*I32 | I32: =$I$7 | J32: =B32/H32 | K32: =AOV | L32: =H32*K32 | M32: =B32/L32 | N32: =L32/B32 | O32: 0.06
A33: SB/Video/Generic Chettinad kws-Exact | B33: =$B$7*O33 | C33: =F33/E33 | D33: =B33/C33*1000 | E33: =$E$7 | F33: =B33/G33 | G33: =$G$7 | H33: =F33*I33 | I33: =$I$7 | J33: =B33/H33 | K33: =AOV | L33: =H33*K33 | M33: =B33/L33 | N33: =L33/B33 | O33: 0.24
A34: SB/Video/Generic Chettinad kws-Phrase | B34: =$B$7*O34 | C34: =F34/E34 | D34: =B34/C34*1000 | E34: =$E$7 | F34: =B34/G34 | G34: =$G$7 | H34: =F34*I34 | I34: =$I$7 | J34: =B34/H34 | K34: =AOV | L34: =H34*K34 | M34: =B34/L34 | N34: =L34/B34 | O34: 0.12
A35: SB/Video/Comp kws-Exact | B35: =$B$7*O35 | C35: =F35/E35 | D35: =B35/C35*1000 | E35: =$E$7 | F35: =B35/G35 | G35: =$G$7 | H35: =F35*I35 | I35: =$I$7 | J35: =B35/H35 | K35: =AOV | L35: =H35*K35 | M35: =B35/L35 | N35: =L35/B35 | O35: 0.1
A36: SB/Video/Comp kws-Phrase | B36: =$B$7*O36 | C36: =F36/E36 | D36: =B36/C36*1000 | E36: =$E$7 | F36: =B36/G36 | G36: =$G$7 | H36: =F36*I36 | I36: =$I$7 | J36: =B36/H36 | K36: =AOV | L36: =H36*K36 | M36: =B36/L36 | N36: =L36/B36 | O36: 0.06
A37: Total SB | B37: =SUM(B30:B36) | C37: =SUM(C30:C36) | D37: =B37/C37*1000 | E37: =F37/C37 | F37: =SUM(F30:F36) | G37: =B37/F37 | H37: =SUM(H30:H36) | I37: =H37/F37 | J37: =B37/H37 | K37: =L37/H37 | L37: =SUM(L30:L36) | M37: =B37/L37 | N37: =L37/B37 | O37: =SUM(O30:O36)
A39: B. SD campaigns
A40: Campaign | B40: Spend | C40: Impressions | D40: CPM | E40: CTR | F40: Clicks | G40: CPC | H40: Orders | I40: CVR | J40: CPA | K40: AOV | L40: Sales | M40: ACOS | N40: ROAS | O40: Share in SD | P40: Why
A41: SD/Remarketing/Views | B41: =$B$8*O41 | C41: =F41/E41 | D41: =B41/C41*1000 | E41: =$E$8 | F41: =B41/G41 | G41: =$G$8 | H41: =F41*I41 | I41: =$I$8 | J41: =B41/H41 | K41: =AOV | L41: =H41*K41 | M41: =B41/L41 | N41: =L41/B41 | O41: 0.35
A42: SD/Remarketing/Purchases | B42: =$B$8*O42 | C42: =F42/E42 | D42: =B42/C42*1000 | E42: =$E$8 | F42: =B42/G42 | G42: =$G$8 | H42: =F42*I42 | I42: =$I$8 | J42: =B42/H42 | K42: =AOV | L42: =H42*K42 | M42: =B42/L42 | N42: =L42/B42 | O42: 0.25 | P42: Repeat buyers add up (deck)
A43: SD/Contextual/IP-Comp | B43: =$B$8*O43 | C43: =F43/E43 | D43: =B43/C43*1000 | E43: =$E$8 | F43: =B43/G43 | G43: =$G$8 | H43: =F43*I43 | I43: =$I$8 | J43: =B43/H43 | K43: =AOV | L43: =H43*K43 | M43: =B43/L43 | N43: =L43/B43 | O43: 0.15
A44: SD/Contextual/CT | B44: =$B$8*O44 | C44: =F44/E44 | D44: =B44/C44*1000 | E44: =$E$8 | F44: =B44/G44 | G44: =$G$8 | H44: =F44*I44 | I44: =$I$8 | J44: =B44/H44 | K44: =AOV | L44: =H44*K44 | M44: =B44/L44 | N44: =L44/B44 | O44: 0.05
...

Sheet Phase Summary
A1: Phase Summary – budget, sales and ROAS by ad type
A3: Phase | B3: Budget | C3: SP | D3: SB | E3: SD | F3: Sales | G3: Orders | H3: ROAS
A4: Month 1 & 2 | B4: ='Month 1 and 2'!B9 | C4: ='Month 1 and 2'!B6 | D4: ='Month 1 and 2'!B7 | E4: ='Month 1 and 2'!B8 | F4: ='Month 1 and 2'!L9 | G4: ='Month 1 and 2'!H9 | H4: ='Month 1 and 2'!N9
